Workbook

Sheet G MTTS
A2: =SUM(AO3:AP3) -> 556 | C2: GLOBAL MTT - SUPREMA POKER
B3: Brazil/Arg | C3: EUA | D3: CANADÁ | E3: MÉX/CR | F3: PERU/COL | G3: VEZ | H3: EU | I3: ÁSIA | Q3: ACTION: 20s | V3: USD | Z3: USD | AG3: BLINDS UP (min) | AO3: =COUNTIF($M$1:$M$990,"main event") -> 65 | AP3: =COUNTIF($M$1:$M$990,"side event") -> 491 | AQ3: =COUNTIF($M$1:$M$990,"sat") -> 266
A4: DAY | B4: HORA | C4: TIME (UTC-5) | D4: TIME (UTC-7) | E4: TIME (UTC-6) | F4: TIME (UTC-5) | G4: TIME (UTC-4) | H4: TIME (UTC+3) | I4: TIME (UTC+8) | J4: MTT MARKETING | L4: MTT | M4: TYPE | N4: Game Type | O4: K.O (REG / PROG / OFF) | P4: MAX. TABLE | Q4: PRIZE POOL USD | R4: TICKET AWARD | S4: PERSONALIZED AWARD | T4: PAYOUT | U4: CALCULATED PAYOUT | V4: BUY-IN | W4: REENTRY/REBUY | X4: STACK REENTRY/REBUY | Y4: REBUY CONDITION | Z4: ADD-ON | AA4: STACK ADD-ON | AB4: BREAK LATE REG. | AC4: FEE | AD4: ADMIN FEE | AE4: STRUCTURE | AF4: CHIPS | AG4: Early game | AH4: Pós Late Reg. | AI4: Final Table | AJ4: LATE REG. | AK4: Num. players | AL4: EARLY BIRD | AM4: CHAT | AN4: TIME BANK | AO4: Hour late register | AP4: Action | AQ4: Size buy-in
A6: MONDAY | C6: 0.083333333 | D6: 0.16666667 | E6: 0.125 | F6: 0.083333333 | G6: 0.041666667 | H6: 0.25 | I6: 0.45833333 | J6: MONDAY | L6: MONDAY | Q6: MONDAY | V6: MONDAY | AB6: MONDAY | AE6: MONDAY | AJ6: MONDAY
A7: MONDAY | B7: 0.58334491 | C7: =TEXT(IF($B7=0," ",$B7-C$6),"hh:mm am/pm") -> 12:00 001/p1 | D7: =TEXT(IF($B7=0," ",$B7-D$6),"hh:mm am/pm") -> 10:00 001/p1 | E7: =TEXT(IF($B7=0," ",$B7-E$6),"hh:mm am/pm") -> 11:00 001/p1 | F7: =TEXT(IF($B7=0," ",$B7-F$6),"hh:mm am/pm") -> 12:00 001/p1 | G7: =TEXT(IF($B7=0," ",$B7-G$6),"hh:mm am/pm") -> 13:00 001/p1 | H7: =TEXT(IF($B7=0," ",$B7+H$6),"hh:mm am/pm") -> 20:00 001/p1 | I7: =TEXT(IF($B7=0," ",$B7+I$6),"hh:mm am/pm") -> 01:00 001/p1 | J7: #AS 25K WarmUp | L7: #AS WarmUp | M7: Main Event | N7: NLH | O7: Progressive KO 1/3 | P7: 8 | Q7: 5000 | R7: n/a | T7: 15% New | U7: Only buy-in | V7: 22 | W7: 22 | Y7: No Limit | AA7: REENTRY | AB7: 5 min | AC7: 0.1 | AD7: 0.02 | AE7: Turbo | AF7: 50000 | AG7: 12 | AH7: 10 | AI7: 10 | AJ7: 15 | AK7: 2-10000 | AL7: Level 0 20% | AM7: Only for in-game players | AN7: Off - ilimitado | AO7: =IF(B7=0," ",TIME(,ROUNDDOWN(AG7*AJ7/60,0)*5+(AG7*AJ7),)+B7) -> 0.71876157 | AP7: =IF(Q7=0,,ROUNDUP(Q7/(V7*(1-AC7-AD7)),0)) -> 259 | AQ7: =IFERROR(IF(V7=0," ",IF(V7<=5,"MICRO",IF(V7<=19.8,"LOW",IF(V7<=99.8,"MEDIUM",IF(V7<=500,"HIGH",IF(V7>500,"SUPER HIGH",)))))),"") -> MEDIUM
A8: Side Event | B8: 0.62501157 | C8: =TEXT(IF($B8=0," ",$B8-C$6),"hh:mm am/pm") -> 13:00 001/p1 | D8: =TEXT(IF($B8=0," ",$B8-D$6),"hh:mm am/pm") -> 11:00 001/p1 | E8: =TEXT(IF($B8=0," ",$B8-E$6),"hh:mm am/pm") -> 12:00 001/p1 | F8: =TEXT(IF($B8=0," ",$B8-F$6),"hh:mm am/pm") -> 13:00 001/p1 | G8: =TEXT(IF($B8=0," ",$B8-G$6),"hh:mm am/pm") -> 14:00 001/p1 | H8: =TEXT(IF($B8=0," ",$B8+H$6),"hh:mm am/pm") -> 21:00 001/p1 | I8: =TEXT(IF($B8=0," ",$B8+I$6),"hh:mm am/pm") -> 02:00 001/p1 | J8: #AS 25K Plus+SPS | L8: #AS Plus+SPS | M8: Main Event | N8: NLH | O8: OFF | P8: 9 | Q8: 5200 | R8: 1 Ticket SPS 76-M Supremo | T8: 15% Flat | U8: Buy-in+Rebuy | V8: 11 | W8: 11 | Y8: No limit + double rebuy | Z8: 11 | AA8: 120000 | AB8: 5 min | AC8: 0.1 | AD8: 0.02 | AE8: Turbo | AF8: 40000 | AG8: 10 | AH8: 10 | AI8: 10 | AJ8: 15 | AK8: 2-10000 | AL8: Level 0 20% | AM8: Only for in-game players | AN8: Off - ilimitado | AO8: =IF(B8=0," ",TIME(,ROUNDDOWN(AG8*AJ8/60,0)*5+(AG8*AJ8),)+B8) -> 0.73612269 | AP8: =IF(Q8=0,,ROUNDUP(Q8/(V8*(1-AC8-AD8)),0)) -> 538 | AQ8: =IFERROR(IF(V8=0," ",IF(V8<=5,"MICRO",IF(V8<=19.8,"LOW",IF(V8<=99.8,"MEDIUM",IF(V8<=500,"HIGH",IF(V8>500,"SUPER HIGH",)))))),"") -> LOW
A9: =COUNTIF(M7:M77,"Side event") -> 60 | B9: 0.66667824 | C9: =TEXT(IF($B9=0," ",$B9-C$6),"hh:mm am/pm") -> 14:00 001/p1 | D9: =TEXT(IF($B9=0," ",$B9-D$6),"hh:mm am/pm") -> 12:00 001/p1 | E9: =TEXT(IF($B9=0," ",$B9-E$6),"hh:mm am/pm") -> 13:00 001/p1 | F9: =TEXT(IF($B9=0," ",$B9-F$6),"hh:mm am/pm") -> 14:00 001/p1 | G9: =TEXT(IF($B9=0," ",$B9-G$6),"hh:mm am/pm") -> 15:00 001/p1 | H9: =TEXT(IF($B9=0," ",$B9+H$6),"hh:mm am/pm") -> 22:00 001/p1 | I9: =TEXT(IF($B9=0," ",$B9+I$6),"hh:mm am/pm") -> 03:00 001/p1 | J9: #AS 20K Bounty | L9: #AS Bounty | M9: Main Event | N9: NLH | O9: Progressive KO 1/2 | P9: 8 | Q9: 4000 | R9: n/a | T9: 15% New | U9: Only buy-in | V9: 16 | W9: 16 | X9: 60000 | Y9: No Limit | AA9: REENTRY | AB9: 5 min | AC9: 0.1 | AD9: 0.02 | AE9: Turbo | AF9: 50000 | AG9: 12 | AH9: 10 | AI9: 10 | AJ9: 15 | AK9: 2-10000 | AL9: Level 0 20% | AM9: Only for in-game players | AN9: Off - ilimitado | AO9: =IF(B9=0," ",TIME(,ROUNDDOWN(AG9*AJ9/60,0)*5+(AG9*AJ9),)+B9) -> 0.80209491 | AP9: =IF(Q9=0,,ROUNDUP(Q9/(V9*(1-AC9-AD9)),0)) -> 285 | AQ9: =IFERROR(IF(V9=0," ",IF(V9<=5,"MICRO",IF(V9<=19.8,"LOW",IF(V9<=99.8,"MEDIUM",IF(V9<=500,"HIGH",IF(V9>500,"SUPER HIGH",)))))),"") -> LOW
A10: Main Event | B10: 0.75001157 | C10: =TEXT(IF($B10=0," ",$B10-C$6),"hh:mm am/pm") -> 16:00 001/p1 | D10: =TEXT(IF($B10=0," ",$B10-D$6),"hh:mm am/pm") -> 14:00 001/p1 | E10: =TEXT(IF($B10=0," ",$B10-E$6),"hh:mm am/pm") -> 15:00 001/p1 | F10: =TEXT(IF($B10=0," ",$B10-F$6),"hh:mm am/pm") -> 16:00 001/p1 | G10: =TEXT(IF($B10=0," ",$B10-G$6),"hh:mm am/pm") -> 17:00 001/p1 | H10: =TEXT(IF($B10=0," ",$B10+H$6),"hh:mm am/pm") -> 00:00 001/p1 | I10: =TEXT(IF($B10=0," ",$B10+I$6),"hh:mm am/pm") -> 05:00 001/p1 | J10: #AS 75K Big Plus+SPS | L10: #AS Big Plus+SPS | M10: Main Event | N10: NLH | O10: OFF | P10: 8 | Q10: 15200 | R10: 1 Ticket SPS 76-M Supremo | T10: 15% Flat | U10: Buy-in+Rebuy | V10: 15 | W10: 15 | Y10: No limit + double rebuy | Z10: 15 | AA10: 120000 | AB10: 5 min | AC10: 0.1 | AD10: 0.02 | AE10: Turbo | AF10: 40000 | AG10: 12 | AH10: 10 | AI10: 10 | AJ10: 15 | AK10: 2-10000 | AL10: Level 0 20% | AM10: Only for in-game players | AN10: Off - ilimitado | AO10: =IF(B10=0," ",TIME(,ROUNDDOWN(AG10*AJ10/60,0)*5+(AG10*AJ10),)+B10) -> 0.88542824 | AP10: =IF(Q10=0,,ROUNDUP(Q10/(V10*(1-AC10-AD10)),0)) -> 1152 | AQ10: =IFERROR(IF(V10=0," ",IF(V10<=5,"MICRO",IF(V10<=19.8,"LOW",IF(V10<=99.8,"MEDIUM",IF(V10<=500,"HIGH",IF(V10>500,"SUPER HIGH",)))))),"") -> LOW
A11: =COUNTIF(M7:M77,"Main Event") -> 10 | B11: 0.75001157 | C11: =TEXT(IF($B11=0," ",$B11-C$6),"hh:mm am/pm") -> 16:00 001/p1 | D11: =TEXT(IF($B11=0," ",$B11-D$6),"hh:mm am/pm") -> 14:00 001/p1 | E11: =TEXT(IF($B11=0," ",$B11-E$6),"hh:mm am/pm") -> 15:00 001/p1 | F11: =TEXT(IF($B11=0," ",$B11-F$6),"hh:mm am/pm") -> 16:00 001/p1 | G11: =TEXT(IF($B11=0," ",$B11-G$6),"hh:mm am/pm") -> 17:00 001/p1 | H11: =TEXT(IF($B11=0," ",$B11+H$6),"hh:mm am/pm") -> 00:00 001/p1 | I11: =TEXT(IF($B11=0," ",$B11+I$6),"hh:mm am/pm") -> 05:00 001/p1 | J11: #AS 100K Plus+SPT | L11: #AS Plus+SPT | M11: Main Event | N11: NLH | O11: OFF | P11: 8 | Q11: 21700 | R11: 1 Pacote SPT2 8.5K BRL | T11: 15% Flat | U11: Buy-in+Rebuy | V11: 5 | W11: 5 | Y11: No limit + double rebuy | Z11: 6 | AA11: 250000 | AB11: 5 min | AC11: 0.1 | AD11: 0.02 | AE11: Hyper turbo | AF11: 50000 | AG11: 10 | AH11: 8 | AI11: 10 | AJ11: 15 | AK11: 2-10000 | AL11: Level 0 20% | AM11: Only for in-game players | AN11: Off - ilimitado | AO11: =IF(B11=0," ",TIME(,ROUNDDOWN(AG11*AJ11/60,0)*5+(AG11*AJ11),)+B11) -> 0.86112269 | AP11: =IF(Q11=0,,ROUNDUP(Q11/(V11*(1-AC11-AD11)),0)) -> 4932 | AQ11: =IFERROR(IF(V11=0," ",IF(V11<=5,"MICRO",IF(V11<=19.8,"LOW",IF(V11<=99.8,"MEDIUM",IF(V11<=500,"HIGH",IF(V11>500,"SUPER HIGH",)))))),"") -> MICRO
A12: Total GTD | B12: 0.77084491 | C12: =TEXT(IF($B12=0," ",$B12-C$6),"hh:mm am/pm") -> 16:30 001/p1 | D12: =TEXT(IF($B12=0," ",$B12-D$6),"hh:mm am/pm") -> 14:30 001/p1 | E12: =TEXT(IF($B12=0," ",$B12-E$6),"hh:mm am/pm") -> 15:30 001/p1 | F12: =TEXT(IF($B12=0," ",$B12-F$6),"hh:mm am/pm") -> 16:30 001/p1 | G12: =TEXT(IF($B12=0," ",$B12-G$6),"hh:mm am/pm") -> 17:30 001/p1 | H12: =TEXT(IF($B12=0," ",$B12+H$6),"hh:mm am/pm") -> 00:30 001/p1 | I12: =TEXT(IF($B12=0," ",$B12+I$6),"hh:mm am/pm") -> 05:30 001/p1 | J12: #AS 100K Battle+SPS | L12: #AS Battle+SPS | M12: Main Event | N12: NLH | O12: Progressive KO 1/2 | P12: 8 | Q12: 20200 | R12: 1 Ticket SPS 76-M Supremo | T12: 15% Plus | U12: Only buy-in | V12: 15 | W12: 15 | Y12: No Limit | AA12: REENTRY | AB12: 5 min | AC12: 0.1 | AD12: 0.02 | AE12: Hyper turbo | AF12: 80000 | AG12: 12 | AH12: 10 | AI12: 10 | AJ12: 15 | AK12: 2-10000 | AL12: Level 0 20% | AM12: Only for in-game players | AN12: Off - ilimitado | AO12: =IF(B12=0," ",TIME(,ROUNDDOWN(AG12*AJ12/60,0)*5+(AG12*AJ12),)+B12) -> 0.90626157 | AP12: =IF(Q12=0,,ROUNDUP(Q12/(V12*(1-AC12-AD12)),0)) -> 1531 | AQ12: =IFERROR(IF(V12=0," ",IF(V12<=5,"MICRO",IF(V12<=19.8,"LOW",IF(V12<=99.8,"MEDIUM",IF(V12<=500,"HIGH",IF(V12>500,"SUPER HIGH",)))))),"") -> LOW
A13: =SUM(Q7:Q77,Q79:Q125) -> 251295 | B13: 0.79167824 | C13: =TEXT(IF($B13=0," ",$B13-C$6),"hh:mm am/pm") -> 17:00 001/p1 | D13: =TEXT(IF($B13=0," ",$B13-D$6),"hh:mm am/pm") -> 15:00 001/p1 | E13: =TEXT(IF($B13=0," ",$B13-E$6),"hh:mm am/pm") -> 16:00 001/p1 | F13: =TEXT(IF($B13=0," ",$B13-F$6),"hh:mm am/pm") -> 17:00 001/p1 | G13: =TEXT(IF($B13=0," ",$B13-G$6),"hh:mm am/pm") -> 18:00 001/p1 | H13: =TEXT(IF($B13=0," ",$B13+H$6),"hh:mm am/pm") -> 01:00 001/p1 | I13: =TEXT(IF($B13=0," ",$B13+I$6),"hh:mm am/pm") -> 06:00 001/p1 | J13: #AS 300K Monday HighS | L13: #AS Monday HighS | M13: Main Event | N13: NLH | O13: Progressive KO 1/2 | P13: 8 | Q13: 60000 | R13: n/a | T13: 15% Plus | U13: Only buy-in | V13: 150 | W13: 150 | X13: 60000 | Y13: No Limit | AA13: REENTRY | AB13: 5 min | AC13: 0.1 | AD13: 0.02 | AE13: Turbo | AF13: 50000 | AG13: 15 | AH13: 12 | AI13: 12 | AJ13: 14 | AK13: 2-10000 | AL13: Level 0 20% | AM13: Only for in-game players | AN13: Off - ilimitado | AO13: =IF(B13=0," ",TIME(,ROUNDDOWN(AG13*AJ13/60,0)*5+(AG13*AJ13),)+B13) -> 0.94792824 | AP13: =IF(Q13=0,,ROUNDUP(Q13/(V13*(1-AC13-AD13)),0)) -> 455 | AQ13: =IFERROR(IF(V13=0," ",IF(V13<=5,"MICRO",IF(V13<=19.8,"LOW",IF(V13<=99.8,"MEDIUM",IF(V13<=500,"HIGH",IF(V13>500,"SUPER HIGH",)))))),"") -> HIGH
B14: 0.79167824 | C14: =TEXT(IF($B14=0," ",$B14-C$6),"hh:mm am/pm") -> 17:00 001/p1 | D14: =TEXT(IF($B14=0," ",$B14-D$6),"hh:mm am/pm") -> 15:00 001/p1 | E14: =TEXT(IF($B14=0," ",$B14-E$6),"hh:mm am/pm") -> 16:00 001/p1 | F14: =TEXT(IF($B14=0," ",$B14-F$6),"hh:mm am/pm") -> 17:00 001/p1 | G14: =TEXT(IF($B14=0," ",$B14-G$6),"hh:mm am/pm") -> 18:00 001/p1 | H14: =TEXT(IF($B14=0," ",$B14+H$6),"hh:mm am/pm") -> 01:00 001/p1 | I14: =TEXT(IF($B14=0," ",$B14+I$6),"hh:mm am/pm") -> 06:00 001/p1 | J14: #AS 150K Battle HR+SPS | L14: #AS Battle HR+SPS | M14: Main Event | N14: NLH | O14: Progressive KO 1/2 | P14: 8 | Q14: 30300 | R14: 1 Ticket SPS 277-M M.E | T14: 15% Plus | U14: Only buy-in | V14: 50 | W14: 50 | X14: 60000 | Y14: No Limit | AA14: REENTRY | AB14: 5 min | AC14: 0.1 | AD14: 0.02 | AE14: Turbo | AF14: 50000 | AG14: 12 | AH14: 12 | AI14: 12 | AJ14: 15 | AK14: 2-10000 | AL14: Level 0 20% | AM14: Only for in-game players | AN14: Off - ilimitado | AO14: =IF(B14=0," ",TIME(,ROUNDDOWN(AG14*AJ14/60,0)*5+(AG14*AJ14),)+B14) -> 0.92709491 | AP14: =IF(Q14=0,,ROUNDUP(Q14/(V14*(1-AC14-AD14)),0)) -> 689 | AQ14: =IFERROR(IF(V14=0," ",IF(V14<=5,"MICRO",IF(V14<=19.8,"LOW",IF(V14<=99.8,"MEDIUM",IF(V14<=500,"HIGH",IF(V14>500,"SUPER HIGH",)))))),"") -> MEDIUM
A15: MONDAY | B15: 0.83334491 | C15: =TEXT(IF($B15=0," ",$B15-C$6),"hh:mm am/pm") -> 18:00 001/p1 | D15: =TEXT(IF($B15=0," ",$B15-D$6),"hh:mm am/pm") -> 16:00 001/p1 | E15: =TEXT(IF($B15=0," ",$B15-E$6),"hh:mm am/pm") -> 17:00 001/p1 | F15: =TEXT(IF($B15=0," ",$B15-F$6),"hh:mm am/pm") -> 18:00 001/p1 | G15: =TEXT(IF($B15=0," ",$B15-G$6),"hh:mm am/pm") -> 19:00 001/p1 | H15: =TEXT(IF($B15=0," ",$B15+H$6),"hh:mm am/pm") -> 02:00 001/p1 | I15: =TEXT(IF($B15=0," ",$B15+I$6),"hh:mm am/pm") -> 07:00 001/p1 | J15: #AS 60K OmaX HR | L15: #AS OmaX HR | M15: Main Event | N15: PLO5 | O15: Progressive KO 1/2 | P15: 6 | Q15: 12000 | R15: n/a | T15: 15% Plus | U15: Buy-in+Rebuy | V15: 110 | W15: 110 | X15: 60000 | Y15: No Limit | AA15: REENTRY | AB15: 5 min | AC15: 0.1 | AD15: 0.02 | AE15: Turbo | AF15: 50000 | AG15: 12 | AH15: 12 | AI15: 12 | AJ15: 15 | AK15: 2-10000 | AL15: Level 0 20% | AM15: Only for in-game players | AN15: Off - ilimitado | AO15: =IF(B15=0," ",TIME(,ROUNDDOWN(AG15*AJ15/60,0)*5+(AG15*AJ15),)+B15) -> 0.96876157 | AP15: =IF(Q15=0,,ROUNDUP(Q15/(V15*(1-AC15-AD15)),0)) -> 124 | AQ15: =IFERROR(IF(V15=0," ",IF(V15<=5,"MICRO",IF(V15<=19.8,"LOW",IF(V15<=99.8,"MEDIUM",IF(V15<=500,"HIGH",IF(V15>500,"SUPER HIGH",)))))),"") -> HIGH
B16: 0.83334491 | C16: =TEXT(IF($B16=0," ",$B16-C$6),"hh:mm am/pm") -> 18:00 001/p1 | D16: =TEXT(IF($B16=0," ",$B16-D$6),"hh:mm am/pm") -> 16:00 001/p1 | E16: =TEXT(IF($B16=0," ",$B16-E$6),"hh:mm am/pm") -> 17:00 001/p1 | F16: =TEXT(IF($B16=0," ",$B16-F$6),"hh:mm am/pm") -> 18:00 001/p1 | G16: =TEXT(IF($B16=0," ",$B16-G$6),"hh:mm am/pm") -> 19:00 001/p1 | H16: =TEXT(IF($B16=0," ",$B16+H$6),"hh:mm am/pm") -> 02:00 001/p1 | I16: =TEXT(IF($B16=0," ",$B16+I$6),"hh:mm am/pm") -> 07:00 001/p1 | J16: #AS 50K Big Mystery+SPS | L16: #AS Big Mystery+SPS | M16: Main Event | N16: NLH | O16: Mystery Bounty 1/2 | P16: 8 | Q16: 10200 | R16: 1 Ticket SPS 76-M Supremo | T16: 15% New | U16: Only buy-in | V16: 22 | W16: 22 | Y16: No Limit | AA16: REENTRY | AB16: 5 min | AC16: 0.1 | AD16: 0.02 | AE16: Hyper turbo | AF16: 60000 | AG16: 10 | AH16: 10 | AI16: 10 | AJ16: 14 | AK16: 2-10000 | AL16: Level 0 20% | AM16: Only for in-game players | AN16: Off - ilimitado | AO16: =IF(B16=0," ",TIME(,ROUNDDOWN(AG16*AJ16/60,0)*5+(AG16*AJ16),)+B16) -> 0.93751157 | AP16: =IF(Q16=0,,ROUNDUP(Q16/(V16*(1-AC16-AD16)),0)) -> 527 | AQ16: =IFERROR(IF(V16=0," ",IF(V16<=5,"MICRO",IF(V16<=19.8,"LOW",IF(V16<=99.8,"MEDIUM",IF(V16<=500,"HIGH",IF(V16>500,"SUPER HIGH",)))))),"") -> MEDIUM
C17: =TEXT(IF($B17=0," ",$B17-C$6),"hh:mm am/pm") | D17: =TEXT(IF($B17=0," ",$B17-D$6),"hh:mm am/pm") | E17: =TEXT(IF($B17=0," ",$B17-E$6),"hh:mm am/pm") | F17: =TEXT(IF($B17=0," ",$B17-F$6),"hh:mm am/pm") | G17: =TEXT(IF($B17=0," ",$B17-G$6),"hh:mm am/pm") | H17: =TEXT(IF($B17=0," ",$B17+H$6),"hh:mm am/pm") | I17: =TEXT(IF($B17=0," ",$B17+I$6),"hh:mm am/pm") | AO17: =IF(B17=0," ",TIME(,ROUNDDOWN(AG17*AJ17/60,0)*5+(AG17*AJ17),)+B17) | AP17: =IF(Q17=0,,ROUNDUP(Q17/(V17*(1-AC17-AD17)),0)) -> 0 | AQ17: =IFERROR(IF(V17=0," ",IF(V17<=5,"MICRO",IF(V17<=19.8,"LOW",IF(V17<=99.8,"MEDIUM",IF(V17<=500,"HIGH",IF(V17>500,"SUPER HIGH",)))))),"")
A18: MONDAY | B18: 1.1574074e-05 | C18: =TEXT(IF($B18=0," ",$B18-C$6),"hh:mm am/pm") -> #VALUE! | D18: =TEXT(IF($B18=0," ",$B18-D$6),"hh:mm am/pm") -> #VALUE! | E18: =TEXT(IF($B18=0," ",$B18-E$6),"hh:mm am/pm") -> #VALUE! | F18: =TEXT(IF($B18=0," ",$B18-F$6),"hh:mm am/pm") -> #VALUE! | G18: =TEXT(IF($B18=0," ",$B18-G$6),"hh:mm am/pm") -> #VALUE! | H18: =TEXT(IF($B18=0," ",$B18+H$6),"hh:mm am/pm") -> 06:00 001/p1 | I18: =TEXT(IF($B18=0," ",$B18+I$6),"hh:mm am/pm") -> 11:00 001/p1 | J18: #AS 6K Sonic+SPS | L18: #AS Sonic+SPS | M18: Side Event | N18: NLH | O18: OFF | P18: 6 | Q18: 1400 | R18: 1 Ticket SPS 76-M Supremo | T18: 15% New | U18: Buy-in+Rebuy | V18: 7 | W18: 7 | Y18: No limit + double rebuy | AA18: REENTRY | AB18: 5 min | AC18: 0.1 | AD18: 0.02 | AE18: Hyper turbo | AF18: 50000 | AG18: 6 | AH18: 5 | AI18: 5 | AJ18: 13 | AK18: 2-10000 | AL18: Level 0 20% | AM18: Only for in-game players | AN18: Off - ilimitado | AO18: =IF(B18=0," ",TIME(,ROUNDDOWN(AG18*AJ18/60,0)*5+(AG18*AJ18),)+B18) -> 0.057650463 | AP18: =IF(Q18=0,,ROUNDUP(Q18/(V18*(1-AC18-AD18)),0)) -> 228 | AQ18: =IFERROR(IF(V18=0," ",IF(V18<=5,"MICRO",IF(V18<=19.8,"LOW",IF(V18<=99.8,"MEDIUM",IF(V18<=500,"HIGH",IF(V18>500,"SUPER HIGH",)))))),"") -> LOW
B19: 1.1574074e-05 | C19: =TEXT(IF($B19=0," ",$B19-C$6),"hh:mm am/pm") -> #VALUE! | D19: =TEXT(IF($B19=0," ",$B19-D$6),"hh:mm am/pm") -> #VALUE! | E19: =TEXT(IF($B19=0," ",$B19-E$6),"hh:mm am/pm") -> #VALUE! | F19: =TEXT(IF($B19=0," ",$B19-F$6),"hh:mm am/pm") -> #VALUE! | G19: =TEXT(IF($B19=0," ",$B19-G$6),"hh:mm am/pm") -> #VALUE! | H19: =TEXT(IF($B19=0," ",$B19+H$6),"hh:mm am/pm") -> 06:00 001/p1 | I19: =TEXT(IF($B19=0," ",$B19+I$6),"hh:mm am/pm") -> 11:00 001/p1 | J19: 1.2K Omax K.O | L19: Omax K.O | M19: Side Event | N19: PLO5 | O19: Regular KO 1/3 | P19: 6 | Q19: 240 | R19: n/a | T19: 15% New | U19: Only buy-in | V19: 2 | W19: 2 | Y19: No Limit | AA19: REENTRY | AB19: 5 min | AC19: 0.1 | AD19: 0 | AE19: Hyper turbo | AF19: 60000 | AG19: 6 | AH19: 5 | AI19: 5 | AJ19: 12 | AK19: 2-10000 | AL19: Level 0 20% | AM19: Only for in-game players | AN19: Off - ilimitado | AO19: =IF(B19=0," ",TIME(,ROUNDDOWN(AG19*AJ19/60,0)*5+(AG19*AJ19),)+B19) -> 0.053483796 | AP19: =IF(Q19=0,,ROUNDUP(Q19/(V19*(1-AC19-AD19)),0)) -> 134 | AQ19: =IFERROR(IF(V19=0," ",IF(V19<=5,"MICRO",IF(V19<=19.8,"LOW",IF(V19<=99.8,"MEDIUM",IF(V19<=500,"HIGH",IF(V19>500,"SUPER HIGH",)))))),"") -> MICRO
B20: 0.013900463 | C20: =TEXT(IF($B20=0," ",$B20-C$6),"hh:mm am/pm") -> #VALUE! | D20: =TEXT(IF($B20=0," ",$B20-D$6),"hh:mm am/pm") -> #VALUE! | E20: =TEXT(IF($B20=0," ",$B20-E$6),"hh:mm am/pm") -> #VALUE! | F20: =TEXT(IF($B20=0," ",$B20-F$6),"hh:mm am/pm") -> #VALUE! | G20: =TEXT(IF($B20=0," ",$B20-G$6),"hh:mm am/pm") -> #VALUE! | H20: =TEXT(IF($B20=0," ",$B20+H$6),"hh:mm am/pm") -> 06:20 001/p1 | I20: =TEXT(IF($B20=0," ",$B20+I$6),"hh:mm am/pm") -> 11:20 001/p1 | J20: 600 Battle Turbo | L20: Battle Turbo | M20: Side Event | N20: NLH | O20: Regular KO 1/3 | P20: 9 | Q20: 120 | R20: n/a | T20: 15% New | U20: Only buy-in | V20: 1 | W20: 1 | Y20: No Limit | AA20: REENTRY | AB20: 5 min | AC20: 0.1 | AD20: 0 | AE20: Regular (padrão) | AF20: 15000 | AG20: 6 | AH20: 5 | AI20: 5 | AJ20: 13 | AK20: 2-10000 | AL20: Level 0 20% | AM20: Only for in-game players | AN20: Off - ilimitado | AO20: =IF(B20=0," ",TIME(,ROUNDDOWN(AG20*AJ20/60,0)*5+(AG20*AJ20),)+B20) -> 0.071539352 | AP20: =IF(Q20=0,,ROUNDUP(Q20/(V20*(1-AC20-AD20)),0)) -> 134 | AQ20: =IFERROR(IF(V20=0," ",IF(V20<=5,"MICRO",IF(V20<=19.8,"LOW",IF(V20<=99.8,"MEDIUM",IF(V20<=500,"HIGH",IF(V20>500,"SUPER HIGH",)))))),"") -> MICRO
A21: MONDAY | B21: 0.020844907 | C21: =TEXT(IF($B21=0," ",$B21-C$6),"hh:mm am/pm") -> #VALUE! | D21: =TEXT(IF($B21=0," ",$B21-D$6),"hh:mm am/pm") -> #VALUE! | E21: =TEXT(IF($B21=0," ",$B21-E$6),"hh:mm am/pm") -> #VALUE! | F21: =TEXT(IF($B21=0," ",$B21-F$6),"hh:mm am/pm") -> #VALUE! | G21: =TEXT(IF($B21=0," ",$B21-G$6),"hh:mm am/pm") -> #VALUE! | H21: =TEXT(IF($B21=0," ",$B21+H$6),"hh:mm am/pm") -> 06:30 001/p1 | I21: =TEXT(IF($B21=0," ",$B21+I$6),"hh:mm am/pm") -> 11:30 001/p1 | J21: 750 Plus | L21: Plus | M21: Side Event | N21: NLH | O21: OFF | P21: 9 | Q21: 150 | R21: n/a | T21: 20% Flat | U21: Only buy-in | V21: 0.4 | W21: 0.4 | Y21: No limit + double rebuy | Z21: 0.4 | AA21: 50000 | AB21: 5 min | AC21: 0.1 | AD21: 0 | AE21: Turbo | AF21: 30000 | AG21: 5 | AH21: 5 | AI21: 5 | AJ21: 13 | AK21: 2-10000 | AL21: Level 0 20% | AM21: Only for in-game players | AN21: Off - ilimitado | AO21: =IF(B21=0," ",TIME(,ROUNDDOWN(AG21*AJ21/60,0)*5+(AG21*AJ21),)+B21) -> 0.069456019 | AP21: =IF(Q21=0,,ROUNDUP(Q21/(V21*(1-AC21-AD21)),0)) -> 417 | AQ21: =IFERROR(IF(V21=0," ",IF(V21<=5,"MICRO",IF(V21<=19.8,"LOW",IF(V21<=99.8,"MEDIUM",IF(V21<=500,"HIGH",IF(V21>500,"SUPER HIGH",)))))),"") -> MICRO
B22: 0.020844907 | C22: =TEXT(IF($B22=0," ",$B22-C$6),"hh:mm am/pm") -> #VALUE! | D22: =TEXT(IF($B22=0," ",$B22-D$6),"hh:mm am/pm") -> #VALUE! | E22: =TEXT(IF($B22=0," ",$B22-E$6),"hh:mm am/pm") -> #VALUE! | F22: =TEXT(IF($B22=0," ",$B22-F$6),"hh:mm am/pm") -> #VALUE! | G22: =TEXT(IF($B22=0," ",$B22-G$6),"hh:mm am/pm") -> #VALUE! | H22: =TEXT(IF($B22=0," ",$B22+H$6),"hh:mm am/pm") -> 06:30 001/p1 | I22: =TEXT(IF($B22=0," ",$B22+I$6),"hh:mm am/pm") -> 11:30 001/p1 | J22: #AS 1.2K Omax | L22: #AS Omax | M22: Side Event | N22: PLO5 | O22: OFF | P22: 6 | Q22: 240 | R22: n/a | T22: 15% New | U22: Only buy-in | V22: 1 | W22: 1 | Y22: No limit + double rebuy | Z22: 1 | AA22: 70000 | AB22: 5 min | AC22: 0.1 | AD22: 0.02 | AE22: Hyper turbo | AF22: 30000 | AG22: 6 | AH22: 5 | AI22: 5 | AJ22: 12 | AK22: 2-10000 | AL22: Level 0 20% | AM22: Only for in-game players | AN22: Off - ilimitado | AO22: =IF(B22=0," ",TIME(,ROUNDDOWN(AG22*AJ22/60,0)*5+(AG22*AJ22),)+B22) -> 0.07431713 | AP22: =IF(Q22=0,,ROUNDUP(Q22/(V22*(1-AC22-AD22)),0)) -> 273 | AQ22: =IFERROR(IF(V22=0," ",IF(V22<=5,"MICRO",IF(V22<=19.8,"LOW",IF(V22<=99.8,"MEDIUM",IF(V22<=500,"HIGH",IF(V22>500,"SUPER HIGH",)))))),"") -> MICRO
B23: 0.041678241 | C23: =TEXT(IF($B23=0," ",$B23-C$6),"hh:mm am/pm") -> #VALUE! | D23: =TEXT(IF($B23=0," ",$B23-D$6),"hh:mm am/pm") -> #VALUE! | E23: =TEXT(IF($B23=0," ",$B23-E$6),"hh:mm am/pm") -> #VALUE! | F23: =TEXT(IF($B23=0," ",$B23-F$6),"hh:mm am/pm") -> #VALUE! | G23: =TEXT(IF($B23=0," ",$B23-G$6),"hh:mm am/pm") -> 00:00 001/p1 | H23: =TEXT(IF($B23=0," ",$B23+H$6),"hh:mm am/pm") -> 07:00 001/p1 | I23: =TEXT(IF($B23=0," ",$B23+I$6),"hh:mm am/pm") -> 12:00 001/p1 | J23: #AS 8K Plus | L23: #AS Plus | M23: Side Event | N23: NLH | O23: OFF | P23: 6 | Q23: 1600 | R23: n/a | T23: 15% Flat | U23: Buy-in+Rebuy | V23: 3 | W23: 3 | Y23: No limit + double rebuy | Z23: 3 | AA23: 160000 | AB23: 5 min | AC23: 0.1 | AD23: 0.02 | AE23: Hyper turbo | AF23: 40000 | AG23: 6 | AH23: 5 | AI23: 5 | AJ23: 13 | AK23: 2-10000 | AL23: Level 0 20% | AM23: Only for in-game players | AN23: Off - ilimitado | AO23: =IF(B23=0," ",TIME(,ROUNDDOWN(AG23*AJ23/60,0)*5+(AG23*AJ23),)+B23) -> 0.09931713 | AP23: =IF(Q23=0,,ROUNDUP(Q23/(V23*(1-AC23-AD23)),0)) -> 607 | AQ23: =IFERROR(IF(V23=0," ",IF(V23<=5,"MICRO",IF(V23<=19.8,"LOW",IF(V23<=99.8,"MEDIUM",IF(V23<=500,"HIGH",IF(V23>500,"SUPER HIGH",)))))),"") -> MICRO
A24: MONDAY | B24: 0.041678241 | C24: =TEXT(IF($B24=0," ",$B24-C$6),"hh:mm am/pm") -> #VALUE! | D24: =TEXT(IF($B24=0," ",$B24-D$6),"hh:mm am/pm") -> #VALUE! | E24: =TEXT(IF($B24=0," ",$B24-E$6),"hh:mm am/pm") -> #VALUE! | F24: =TEXT(IF($B24=0," ",$B24-F$6),"hh:mm am/pm") -> #VALUE! | G24: =TEXT(IF($B24=0," ",$B24-G$6),"hh:mm am/pm") -> 00:00 001/p1 | H24: =TEXT(IF($B24=0," ",$B24+H$6),"hh:mm am/pm") -> 07:00 001/p1 | I24: =TEXT(IF($B24=0," ",$B24+I$6),"hh:mm am/pm") -> 12:00 001/p1 | J24: #AS 2.5K Omax K.O | L24: #AS Omax K.O | M24: Side Event | N24: PLO4 | O24: Regular KO 1/3 | P24: 6 | Q24: 500 | R24: n/a | T24: 15% New | U24: Only buy-in | V24: 10 | W24: 10 | Y24: No Limit | AA24: REENTRY | AB24: 5 min | AC24: 0.1 | AD24: 0.02 | AE24: Turbo | AF24: 50000 | AG24: 6 | AH24: 5 | AI24: 5 | AJ24: 15 | AK24: 2-10000 | AL24: Level 0 20% | AM24: Only for in-game players | AN24: Off - ilimitado | AO24: =IF(B24=0," ",TIME(,ROUNDDOWN(AG24*AJ24/60,0)*5+(AG24*AJ24),)+B24) -> 0.10765046 | AP24: =IF(Q24=0,,ROUNDUP(Q24/(V24*(1-AC24-AD24)),0)) -> 57 | AQ24: =IFERROR(IF(V24=0," ",IF(V24<=5,"MICRO",IF(V24<=19.8,"LOW",IF(V24<=99.8,"MEDIUM",IF(V24<=500,"HIGH",IF(V24>500,"SUPER HIGH",)))))),"") -> LOW
B25: 0.062511574 | C25: =TEXT(IF($B25=0," ",$B25-C$6),"hh:mm am/pm") -> #VALUE! | D25: =TEXT(IF($B25=0," ",$B25-D$6),"hh:mm am/pm") -> #VALUE! | E25: =TEXT(IF($B25=0," ",$B25-E$6),"hh:mm am/pm") -> #VALUE! | F25: =TEXT(IF($B25=0," ",$B25-F$6),"hh:mm am/pm") -> #VALUE! | G25: =TEXT(IF($B25=0," ",$B25-G$6),"hh:mm am/pm") -> 00:30 001/p1 | H25: =TEXT(IF($B25=0," ",$B25+H$6),"hh:mm am/pm") -> 07:30 001/p1 | I25: =TEXT(IF($B25=0," ",$B25+I$6),"hh:mm am/pm") -> 12:30 001/p1 | J25: 500 Omax PKO | L25: Omax PKO | M25: Side Event | N25: PLO5 | O25: Progressive KO 1/2 | P25: 6 | Q25: 100 | R25: n/a | T25: 15% New | U25: Only buy-in | V25: 0.6 | W25: 0.6 | Y25: No Limit | AA25: REENTRY | AB25: 5 min | AC25: 0.1 | AD25: 0 | AE25: Turbo | AF25: 30000 | AG25: 5 | AH25: 5 | AI25: 5 | AJ25: 13 | AK25: 2-10000 | AL25: Level 0 20% | AM25: Only for in-game players | AN25: Off - ilimitado | AO25: =IF(B25=0," ",TIME(,ROUNDDOWN(AG25*AJ25/60,0)*5+(AG25*AJ25),)+B25) -> 0.11112269 | AP25: =IF(Q25=0,,ROUNDUP(Q25/(V25*(1-AC25-AD25)),0)) -> 186 | AQ25: =IFERROR(IF(V25=0," ",IF(V25<=5,"MICRO",IF(V25<=19.8,"LOW",IF(V25<=99.8,"MEDIUM",IF(V25<=500,"HIGH",IF(V25>500,"SUPER HIGH",)))))),"") -> MICRO
B26: 0.083344907 | C26: =TEXT(IF($B26=0," ",$B26-C$6),"hh:mm am/pm") -> 00:00 001/p1 | D26: =TEXT(IF($B26=0," ",$B26-D$6),"hh:mm am/pm") -> #VALUE! | E26: =TEXT(IF($B26=0," ",$B26-E$6),"hh:mm am/pm") -> #VALUE! | F26: =TEXT(IF($B26=0," ",$B26-F$6),"hh:mm am/pm") -> 00:00 001/p1 | G26: =TEXT(IF($B26=0," ",$B26-G$6),"hh:mm am/pm") -> 01:00 001/p1 | H26: =TEXT(IF($B26=0," ",$B26+H$6),"hh:mm am/pm") -> 08:00 001/p1 | I26: =TEXT(IF($B26=0," ",$B26+I$6),"hh:mm am/pm") -> 13:00 001/p1 | J26: #AS 5K Battle | L26: #AS Battle | M26: Side Event | N26: NLH | O26: Progressive KO 1/2 | P26: 8 | Q26: 1000 | R26: n/a | T26: 15% New | U26: Only buy-in | V26: 7 | W26: 7 | Y26: No Limit | AA26: REENTRY | AB26: 5 min | AC26: 0.1 | AD26: 0.02 | AE26: Hyper turbo | AF26: 40000 | AG26: 6 | AH26: 5 | AI26: 5 | AJ26: 13 | AK26: 2-10000 | AL26: Level 0 20% | AM26: Only for in-game players | AN26: Off - ilimitado | AO26: =IF(B26=0," ",TIME(,ROUNDDOWN(AG26*AJ26/60,0)*5+(AG26*AJ26),)+B26) -> 0.1409838 | AP26: =IF(Q26=0,,ROUNDUP(Q26/(V26*(1-AC26-AD26)),0)) -> 163 | AQ26: =IFERROR(IF(V26=0," ",IF(V26<=5,"MICRO",IF(V26<=19.8,"LOW",IF(V26<=99.8,"MEDIUM",IF(V26<=500,"HIGH",IF(V26>500,"SUPER HIGH",)))))),"") -> LOW
A27: MONDAY | B27: 0.10417824 | C27: =TEXT(IF($B27=0," ",$B27-C$6),"hh:mm am/pm") -> 00:30 001/p1 | D27: =TEXT(IF($B27=0," ",$B27-D$6),"hh:mm am/pm") -> #VALUE! | E27: =TEXT(IF($B27=0," ",$B27-E$6),"hh:mm am/pm") -> #VALUE! | F27: =TEXT(IF($B27=0," ",$B27-F$6),"hh:mm am/pm") -> 00:30 001/p1 | G27: =TEXT(IF($B27=0," ",$B27-G$6),"hh:mm am/pm") -> 01:30 001/p1 | H27: =TEXT(IF($B27=0," ",$B27+H$6),"hh:mm am/pm") -> 08:30 001/p1 | I27: =TEXT(IF($B27=0," ",$B27+I$6),"hh:mm am/pm") -> 13:30 001/p1 | J27: 1.2K Plus | L27: Plus | M27: Side Event | N27: NLH | O27: OFF | P27: 6 | Q27: 240 | R27: n/a | T27: 20% Flat | U27: Only buy-in | V27: 0.6 | W27: 0.6 | Y27: No limit + double rebuy | Z27: 0.8 | AA27: 100000 | AB27: 5 min | AC27: 0.1 | AD27: 0 | AE27: Hyper turbo | AF27: 50000 | AG27: 5 | AH27: 5 | AI27: 5 | AJ27: 13 | AK27: 2-10000 | AL27: Level 0 20% | AM27: Only for in-game players | AN27: Off - ilimitado | AO27: =IF(B27=0," ",TIME(,ROUNDDOWN(AG27*AJ27/60,0)*5+(AG27*AJ27),)+B27) -> 0.15278935 | AP27: =IF(Q27=0,,ROUNDUP(Q27/(V27*(1-AC27-AD27)),0)) -> 445 | AQ27: =IFERROR(IF(V27=0," ",IF(V27<=5,"MICRO",IF(V27<=19.8,"LOW",IF(V27<=99.8,"MEDIUM",IF(V27<=500,"HIGH",IF(V27>500,"SUPER HIGH",)))))),"") -> MICRO
B28: 0.13195602 | C28: =TEXT(IF($B28=0," ",$B28-C$6),"hh:mm am/pm") -> 01:10 001/p1 | D28: =TEXT(IF($B28=0," ",$B28-D$6),"hh:mm am/pm") -> #VALUE! | E28: =TEXT(IF($B28=0," ",$B28-E$6),"hh:mm am/pm") -> 00:10 001/p1 | F28: =TEXT(IF($B28=0," ",$B28-F$6),"hh:mm am/pm") -> 01:10 001/p1 | G28: =TEXT(IF($B28=0," ",$B28-G$6),"hh:mm am/pm") -> 02:10 001/p1 | H28: =TEXT(IF($B28=0," ",$B28+H$6),"hh:mm am/pm") -> 09:10 001/p1 | I28: =TEXT(IF($B28=0," ",$B28+I$6),"hh:mm am/pm") -> 14:10 001/p1 | J28: 800 Omax | L28: Omax | M28: Side Event | N28: PLO5 | O28: OFF | P28: 6 | Q28: 160 | R28: n/a | T28: 15% New | U28: Only buy-in | V28: 2 | W28: 2 | Y28: No limit + double rebuy | Z28: 2 | AA28: 75000 | AB28: 5 min | AC28: 0.1 | AD28: 0 | AE28: Hyper turbo | AF28: 30000 | AG28: 5 | AH28: 5 | AI28: 5 | AJ28: 12 | AK28: 2-10000 | AL28: Level 0 20% | AM28: Only for in-game players | AN28: Off - ilimitado | AO28: =IF(B28=0," ",TIME(,ROUNDDOWN(AG28*AJ28/60,0)*5+(AG28*AJ28),)+B28) -> 0.17709491 | AP28: =IF(Q28=0,,ROUNDUP(Q28/(V28*(1-AC28-AD28)),0)) -> 89 | AQ28: =IFERROR(IF(V28=0," ",IF(V28<=5,"MICRO",IF(V28<=19.8,"LOW",IF(V28<=99.8,"MEDIUM",IF(V28<=500,"HIGH",IF(V28>500,"SUPER HIGH",)))))),"") -> MICRO
B29: 0.13195602 | C29: =TEXT(IF($B29=0," ",$B29-C$6),"hh:mm am/pm") -> 01:10 001/p1 | D29: =TEXT(IF($B29=0," ",$B29-D$6),"hh:mm am/pm") -> #VALUE! | E29: =TEXT(IF($B29=0," ",$B29-E$6),"hh:mm am/pm") -> 00:10 001/p1 | F29: =TEXT(IF($B29=0," ",$B29-F$6),"hh:mm am/pm") -> 01:10 001/p1 | G29: =TEXT(IF($B29=0," ",$B29-G$6),"hh:mm am/pm") -> 02:10 001/p1 | H29: =TEXT(IF($B29=0," ",$B29+H$6),"hh:mm am/pm") -> 09:10 001/p1 | I29: =TEXT(IF($B29=0," ",$B29+I$6),"hh:mm am/pm") -> 14:10 001/p1 | J29: #AS 1.25K Battle | L29: #AS Battle | M29: Side Event | N29: NLH | O29: Progressive KO 1/2 | P29: 8 | Q29: 250 | R29: n/a | T29: 15% New | U29: Only buy-in | V29: 5 | W29: 5 | Y29: No Limit | AA29: REENTRY | AB29: 5 min | AC29: 0.1 | AD29: 0.02 | AE29: Hyper turbo | AF29: 30000 | AG29: 5 | AH29: 5 | AI29: 5 | AJ29: 12 | AK29: 2-10000 | AL29: Level 0 20% | AM29: Only for in-game players | AN29: Off - ilimitado | AO29: =IF(B29=0," ",TIME(,ROUNDDOWN(AG29*AJ29/60,0)*5+(AG29*AJ29),)+B29) -> 0.17709491 | AP29: =IF(Q29=0,,ROUNDUP(Q29/(V29*(1-AC29-AD29)),0)) -> 57 | AQ29: =IFERROR(IF(V29=0," ",IF(V29<=5,"MICRO",IF(V29<=19.8,"LOW",IF(V29<=99.8,"MEDIUM",IF(V29<=500,"HIGH",IF(V29>500,"SUPER HIGH",)))))),"") -> MICRO
A30: MONDAY | B30: 0.17362269 | C30: =TEXT(IF($B30=0," ",$B30-C$6),"hh:mm am/pm") -> 02:10 001/p1 | D30: =TEXT(IF($B30=0," ",$B30-D$6),"hh:mm am/pm") -> 00:10 001/p1 | E30: =TEXT(IF($B30=0," ",$B30-E$6),"hh:mm am/pm") -> 01:10 001/p1 | F30: =TEXT(IF($B30=0," ",$B30-F$6),"hh:mm am/pm") -> 02:10 001/p1 | G30: =TEXT(IF($B30=0," ",$B30-G$6),"hh:mm am/pm") -> 03:10 001/p1 | H30: =TEXT(IF($B30=0," ",$B30+H$6),"hh:mm am/pm") -> 10:10 001/p1 | I30: =TEXT(IF($B30=0," ",$B30+I$6),"hh:mm am/pm") -> 15:10 001/p1 | J30: #AS 1.25K Plus | L30: #AS Plus | M30: Side Event | N30: NLH | O30: OFF | P30: 8 | Q30: 250 | R30: n/a | T30: 20% Flat | U30: Only buy-in | V30: 2 | W30: 2 | Y30: No limit + double rebuy | Z30: 2 | AA30: 75000 | AB30: 5 min | AC30: 0.1 | AD30: 0.02 | AE30: Hyper turbo | AF30: 30000 | AG30: 5 | AH30: 5 | AI30: 5 | AJ30: 12 | AK30: 2-10000 | AL30: Level 0 20% | AM30: Only for in-game players | AN30: Off - ilimitado | AO30: =IF(B30=0," ",TIME(,ROUNDDOWN(AG30*AJ30/60,0)*5+(AG30*AJ30),)+B30) -> 0.21876157 | AP30: =IF(Q30=0,,ROUNDUP(Q30/(V30*(1-AC30-AD30)),0)) -> 143 | AQ30: =IFERROR(IF(V30=0," ",IF(V30<=5,"MICRO",IF(V30<=19.8,"LOW",IF(V30<=99.8,"MEDIUM",IF(V30<=500,"HIGH",IF(V30>500,"SUPER HIGH",)))))),"") -> MICRO
B31: 0.20834491 | C31: =TEXT(IF($B31=0," ",$B31-C$6),"hh:mm am/pm") -> 03:00 001/p1 | D31: =TEXT(IF($B31=0," ",$B31-D$6),"hh:mm am/pm") -> 01:00 001/p1 | E31: =TEXT(IF($B31=0," ",$B31-E$6),"hh:mm am/pm") -> 02:00 001/p1 | F31: =TEXT(IF($B31=0," ",$B31-F$6),"hh:mm am/pm") -> 03:00 001/p1 | G31: =TEXT(IF($B31=0," ",$B31-G$6),"hh:mm am/pm") -> 04:00 001/p1 | H31: =TEXT(IF($B31=0," ",$B31+H$6),"hh:mm am/pm") -> 11:00 001/p1 | I31: =TEXT(IF($B31=0," ",$B31+I$6),"hh:mm am/pm") -> 16:00 001/p1 | J31: 500 Bounty | L31: Bounty | M31: Side Event | N31: NLH | O31: Progressive KO 1/3 | P31: 8 | Q31: 100 | R31: n/a | T31: 15% New | U31: Only buy-in | V31: 1.6 | W31: 1.6 | Y31: No Limit | AA31: REENTRY | AB31: 5 min | AC31: 0.1 | AD31: 0 | AE31: Turbo | AF31: 40000 | AG31: 8 | AH31: 7 | AI31: 7 | AJ31: 14 | AK31: 2-10000 | AL31: Level 0 20% | AM31: Only for in-game players | AN31: Off - ilimitado | AO31: =IF(B31=0," ",TIME(,ROUNDDOWN(AG31*AJ31/60,0)*5+(AG31*AJ31),)+B31) -> 0.28959491 | AP31: =IF(Q31=0,,ROUNDUP(Q31/(V31*(1-AC31-AD31)),0)) -> 70 | AQ31: =IFERROR(IF(V31=0," ",IF(V31<=5,"MICRO",IF(V31<=19.8,"LOW",IF(V31<=99.8,"MEDIUM",IF(V31<=500,"HIGH",IF(V31>500,"SUPER HIGH",)))))),"") -> MICRO
B32: 0.21528935 | C32: =TEXT(IF($B32=0," ",$B32-C$6),"hh:mm am/pm") -> 03:10 001/p1 | D32: =TEXT(IF($B32=0," ",$B32-D$6),"hh:mm am/pm") -> 01:10 001/p1 | E32: =TEXT(IF($B32=0," ",$B32-E$6),"hh:mm am/pm") -> 02:10 001/p1 | F32: =TEXT(IF($B32=0," ",$B32-F$6),"hh:mm am/pm") -> 03:10 001/p1 | G32: =TEXT(IF($B32=0," ",$B32-G$6),"hh:mm am/pm") -> 04:10 001/p1 | H32: =TEXT(IF($B32=0," ",$B32+H$6),"hh:mm am/pm") -> 11:10 001/p1 | I32: =TEXT(IF($B32=0," ",$B32+I$6),"hh:mm am/pm") -> 16:10 001/p1 | J32: 1K Plus | L32: Plus | M32: Side Event | N32: NLH | O32: OFF | P32: 8 | Q32: 200 | R32: n/a | T32: 20% Flat | U32: Only buy-in | V32: 2 | W32: S | Y32: No limit + double rebuy | Z32: 2 | AA32: 80000 | AB32: 5 min | AC32: 0.1 | AD32: 0 | AE32: Hyper turbo | AF32: 40000 | AG32: 6 | AH32: 6 | AI32: 6 | AJ32: 13 | AK32: 2-10000 | AL32: Level 0 20% | AM32: Only for in-game players | AN32: Off - ilimitado | AO32: =IF(B32=0," ",TIME(,ROUNDDOWN(AG32*AJ32/60,0)*5+(AG32*AJ32),)+B32) -> 0.27292824 | AP32: =IF(Q32=0,,ROUNDUP(Q32/(V32*(1-AC32-AD32)),0)) -> 112 | AQ32: =IFERROR(IF(V32=0," ",IF(V32<=5,"MICRO",IF(V32<=19.8,"LOW",IF(V32<=99.8,"MEDIUM",IF(V32<=500,"HIGH",IF(V32>500,"SUPER HIGH",)))))),"") -> MICRO
B33: 0.25695602 | C33: =TEXT(IF($B33=0," ",$B33-C$6),"hh:mm am/pm") -> 04:10 001/p1 | D33: =TEXT(IF($B33=0," ",$B33-D$6),"hh:mm am/pm") -> 02:10 001/p1 | E33: =TEXT(IF($B33=0," ",$B33-E$6),"hh:mm am/pm") -> 03:10 001/p1 | F33: =TEXT(IF($B33=0," ",$B33-F$6),"hh:mm am/pm") -> 04:10 001/p1 | G33: =TEXT(IF($B33=0," ",$B33-G$6),"hh:mm am/pm") -> 05:10 001/p1 | H33: =TEXT(IF($B33=0," ",$B33+H$6),"hh:mm am/pm") -> 12:10 001/p1 | I33: =TEXT(IF($B33=0," ",$B33+I$6),"hh:mm am/pm") -> 17:10 001/p1 | J33: 500 Plus | L33: Plus | M33: Side Event | N33: NLH | O33: OFF | P33: 9 | Q33: 100 | R33: n/a | T33: 20% Flat | U33: Only buy-in | V33: 1 | W33: 1 | Y33: No limit + double rebuy | Z33: 1 | AA33: 80000 | AB33: 5 min | AC33: 0.1 | AD33: 0 | AE33: Hyper turbo | AF33: 40000 | AG33: 6 | AH33: 6 | AI33: 6 | AJ33: 13 | AK33: 2-10000 | AL33: Level 0 20% | AM33: Only for in-game players | AN33: Off - ilimitado | AO33: =IF(B33=0," ",TIME(,ROUNDDOWN(AG33*AJ33/60,0)*5+(AG33*AJ33),)+B33) -> 0.31459491 | AP33: =IF(Q33=0,,ROUNDUP(Q33/(V33*(1-AC33-AD33)),0)) -> 112 | AQ33: =IFERROR(IF(V33=0," ",IF(V33<=5,"MICRO",IF(V33<=19.8,"LOW",IF(V33<=99.8,"MEDIUM",IF(V33<=500,"HIGH",IF(V33>500,"SUPER HIGH",)))))),"") -> MICRO
B34: 0.29862269 | C34: =TEXT(IF($B34=0," ",$B34-C$6),"hh:mm am/pm") -> 05:10 001/p1 | D34: =TEXT(IF($B34=0," ",$B34-D$6),"hh:mm am/pm") -> 03:10 001/p1 | E34: =TEXT(IF($B34=0," ",$B34-E$6),"hh:mm am/pm") -> 04:10 001/p1 | F34: =TEXT(IF($B34=0," ",$B34-F$6),"hh:mm am/pm") -> 05:10 001/p1 | G34: =TEXT(IF($B34=0," ",$B34-G$6),"hh:mm am/pm") -> 06:10 001/p1 | H34: =TEXT(IF($B34=0," ",$B34+H$6),"hh:mm am/pm") -> 13:10 001/p1 | I34: =TEXT(IF($B34=0," ",$B34+I$6),"hh:mm am/pm") -> 18:10 001/p1 | J34: 500 Omax | L34: Omax | M34: Side Event | N34: PLO5 | O34: OFF | P34: 6 | Q34: 100 | R34: n/a | T34: 15% New | U34: Only buy-in | V34: 1 | W34: 1 | Y34: No limit + double rebuy | Z34: 1 | AA34: 75000 | AB34: 5 min | AC34: 0.1 | AD34: 0 | AE34: Hyper turbo | AF34: 30000 | AG34: 5 | AH34: 5 | AI34: 5 | AJ34: 12 | AK34: 2-10000 | AL34: Level 0 20% | AM34: Only for in-game players | AN34: Off - ilimitado | AO34: =IF(B34=0," ",TIME(,ROUNDDOWN(AG34*AJ34/60,0)*5+(AG34*AJ34),)+B34) -> 0.34376157 | AP34: =IF(Q34=0,,ROUNDUP(Q34/(V34*(1-AC34-AD34)),0)) -> 112 | AQ34: =IFERROR(IF(V34=0," ",IF(V34<=5,"MICRO",IF(V34<=19.8,"LOW",IF(V34<=99.8,"MEDIUM",IF(V34<=500,"HIGH",IF(V34>500,"SUPER HIGH",)))))),"") -> MICRO
B35: 0.32292824 | C35: =TEXT(IF($B35=0," ",$B35-C$6),"hh:mm am/pm") -> 05:45 001/p1 | D35: =TEXT(IF($B35=0," ",$B35-D$6),"hh:mm am/pm") -> 03:45 001/p1 | E35: =TEXT(IF($B35=0," ",$B35-E$6),"hh:mm am/pm") -> 04:45 001/p1 | F35: =TEXT(IF($B35=0," ",$B35-F$6),"hh:mm am/pm") -> 05:45 001/p1 | G35: =TEXT(IF($B35=0," ",$B35-G$6),"hh:mm am/pm") -> 06:45 001/p1 | H35: =TEXT(IF($B35=0," ",$B35+H$6),"hh:mm am/pm") -> 13:45 001/p1 | I35: =TEXT(IF($B35=0," ",$B35+I$6),"hh:mm am/pm") -> 18:45 001/p1 | J35: #AS 1.5K Omax PKO | L35: #AS Omax PKO | M35: Side Event | N35: PLO4 | O35: Progressive KO 1/2 | P35: 6 | Q35: 300 | R35: n/a | T35: 15% New | U35: Only buy-in | V35: 3 | W35: 3 | Y35: No Limit | AA35: REENTRY | AB35: 5 min | AC35: 0.1 | AD35: 0.02 | AE35: Turbo | AF35: 40000 | AG35: 10 | AH35: 8 | AI35: 8 | AJ35: 14 | AK35: 2-10000 | AL35: Level 0 20% | AM35: Only for in-game players | AN35: Off - ilimitado | AO35: =IF(B35=0," ",TIME(,ROUNDDOWN(AG35*AJ35/60,0)*5+(AG35*AJ35),)+B35) -> 0.42709491 | AP35: =IF(Q35=0,,ROUNDUP(Q35/(V35*(1-AC35-AD35)),0)) -> 114 | AQ35: =IFERROR(IF(V35=0," ",IF(V35<=5,"MICRO",IF(V35<=19.8,"LOW",IF(V35<=99.8,"MEDIUM",IF(V35<=500,"HIGH",IF(V35>500,"SUPER HIGH",)))))),"") -> MICRO
B36: 0.33334491 | C36: =TEXT(IF($B36=0," ",$B36-C$6),"hh:mm am/pm") -> 06:00 001/p1 | D36: =TEXT(IF($B36=0," ",$B36-D$6),"hh:mm am/pm") -> 04:00 001/p1 | E36: =TEXT(IF($B36=0," ",$B36-E$6),"hh:mm am/pm") -> 05:00 001/p1 | F36: =TEXT(IF($B36=0," ",$B36-F$6),"hh:mm am/pm") -> 06:00 001/p1 | G36: =TEXT(IF($B36=0," ",$B36-G$6),"hh:mm am/pm") -> 07:00 001/p1 | H36: =TEXT(IF($B36=0," ",$B36+H$6),"hh:mm am/pm") -> 14:00 001/p1 | I36: =TEXT(IF($B36=0," ",$B36+I$6),"hh:mm am/pm") -> 19:00 001/p1 | J36: #AS 2.5K Plus | L36: #AS Plus | M36: Side Event | N36: NLH | O36: OFF | P36: 9 | Q36: 500 | R36: n/a | T36: 20% Flat | U36: Only buy-in | V36: 1 | W36: 1 | Y36: No limit + double rebuy | Z36: 1 | AA36: 120000 | AB36: 5 min | AC36: 0.1 | AD36: 0.02 | AE36: Turbo | AF36: 40000 | AG36: 8 | AH36: 7 | AI36: 7 | AJ36: 15 | AK36: 2-10000 | AL36: Level 0 20% | AM36: Only for in-game players | AN36: Off - ilimitado | AO36: =IF(B36=0," ",TIME(,ROUNDDOWN(AG36*AJ36/60,0)*5+(AG36*AJ36),)+B36) -> 0.42362269 | AP36: =IF(Q36=0,,ROUNDUP(Q36/(V36*(1-AC36-AD36)),0)) -> 569 | AQ36: =IFERROR(IF(V36=0," ",IF(V36<=5,"MICRO",IF(V36<=19.8,"LOW",IF(V36<=99.8,"MEDIUM",IF(V36<=500,"HIGH",IF(V36>500,"SUPER HIGH",)))))),"") -> MICRO
A37: MONDAY | B37: 0.3472338 | C37: =TEXT(IF($B37=0," ",$B37-C$6),"hh:mm am/pm") -> 06:20 001/p1 | D37: =TEXT(IF($B37=0," ",$B37-D$6),"hh:mm am/pm") -> 04:20 001/p1 | E37: =TEXT(IF($B37=0," ",$B37-E$6),"hh:mm am/pm") -> 05:20 001/p1 | F37: =TEXT(IF($B37=0," ",$B37-F$6),"hh:mm am/pm") -> 06:20 001/p1 | G37: =TEXT(IF($B37=0," ",$B37-G$6),"hh:mm am/pm") -> 07:20 001/p1 | H37: =TEXT(IF($B37=0," ",$B37+H$6),"hh:mm am/pm") -> 14:20 001/p1 | I37: =TEXT(IF($B37=0," ",$B37+I$6),"hh:mm am/pm") -> 19:20 001/p1 | J37: 300 Plus | L37: Plus | M37: Side Event | N37: NLH | O37: OFF | P37: 9 | Q37: 60 | R37: n/a | T37: 15% Flat | U37: Only buy-in | V37: 0.2 | W37: 0.2 | Y37: No limit + double rebuy | Z37: 0.2 | AA37: 50000 | AB37: 5 min | AC37: 0.1 | AD37: 0 | AE37: Turbo | AF37: 20000 | AG37: 6 | AH37: 5 | AI37: 5 | AJ37: 13 | AK37: 2-10000 | AL37: Level 0 20% | AM37: Only for in-game players | AN37: Off - ilimitado | AO37: =IF(B37=0," ",TIME(,ROUNDDOWN(AG37*AJ37/60,0)*5+(AG37*AJ37),)+B37) -> 0.40487269 | AP37: =IF(Q37=0,,ROUNDUP(Q37/(V37*(1-AC37-AD37)),0)) -> 334 | AQ37: =IFERROR(IF(V37=0," ",IF(V37<=5,"MICRO",IF(V37<=19.8,"LOW",IF(V37<=99.8,"MEDIUM",IF(V37<=500,"HIGH",IF(V37>500,"SUPER HIGH",)))))),"") -> MICRO
B38: 0.37501157 | C38: =TEXT(IF($B38=0," ",$B38-C$6),"hh:mm am/pm") -> 07:00 001/p1 | D38: =TEXT(IF($B38=0," ",$B38-D$6),"hh:mm am/pm") -> 05:00 001/p1 | E38: =TEXT(IF($B38=0," ",$B38-E$6),"hh:mm am/pm") -> 06:00 001/p1 | F38: =TEXT(IF($B38=0," ",$B38-F$6),"hh:mm am/pm") -> 07:00 001/p1 | G38: =TEXT(IF($B38=0," ",$B38-G$6),"hh:mm am/pm") -> 08:00 001/p1 | H38: =TEXT(IF($B38=0," ",$B38+H$6),"hh:mm am/pm") -> 15:00 001/p1 | I38: =TEXT(IF($B38=0," ",$B38+I$6),"hh:mm am/pm") -> 20:00 001/p1 | J38: 750 Bounty | L38: Bounty | M38: Side Event | N38: NLH | O38: Progressive KO 1/3 | P38: 8 | Q38: 150 | R38: n/a | T38: 15% New | U38: Only buy-in | V38: 1.5 | W38: 1.5 | X38: 60000 | Y38: No Limit | AA38: REENTRY | AB38: 5 min | AC38: 0.1 | AD38: 0 | AE38: Turbo | AF38: 50000 | AG38: 8 | AH38: 7 | AI38: 7 | AJ38: 15 | AK38: 2-10000 | AL38: Level 0 20% | AM38: Only for in-game players | AN38: Off - ilimitado | AO38: =IF(B38=0," ",TIME(,ROUNDDOWN(AG38*AJ38/60,0)*5+(AG38*AJ38),)+B38) -> 0.46528935 | AP38: =IF(Q38=0,,ROUNDUP(Q38/(V38*(1-AC38-AD38)),0)) -> 112 | AQ38: =IFERROR(IF(V38=0," ",IF(V38<=5,"MICRO",IF(V38<=19.8,"LOW",IF(V38<=99.8,"MEDIUM",IF(V38<=500,"HIGH",IF(V38>500,"SUPER HIGH",)))))),"") -> MICRO
B39: 0.37501157 | C39: =TEXT(IF($B39=0," ",$B39-C$6),"hh:mm am/pm") -> 07:00 001/p1 | D39: =TEXT(IF($B39=0," ",$B39-D$6),"hh:mm am/pm") -> 05:00 001/p1 | E39: =TEXT(IF($B39=0," ",$B39-E$6),"hh:mm am/pm") -> 06:00 001/p1 | F39: =TEXT(IF($B39=0," ",$B39-F$6),"hh:mm am/pm") -> 07:00 001/p1 | G39: =TEXT(IF($B39=0," ",$B39-G$6),"hh:mm am/pm") -> 08:00 001/p1 | H39: =TEXT(IF($B39=0," ",$B39+H$6),"hh:mm am/pm") -> 15:00 001/p1 | I39: =TEXT(IF($B39=0," ",$B39+I$6),"hh:mm am/pm") -> 20:00 001/p1 | J39: 500 Omax | L39: Omax | M39: Side Event | N39: PLO4 | O39: OFF | P39: 6 | Q39: 100 | R39: n/a | T39: 15% New | U39: Only buy-in | V39: 1 | W39: 1 | Y39: No limit + double rebuy | Z39: 1 | AA39: 80000 | AB39: 5 min | AC39: 0.1 | AD39: 0 | AE39: Hyper turbo | AF39: 40000 | AG39: 7 | AH39: 7 | AI39: 7 | AJ39: 13 | AK39: 2-10000 | AL39: Level 0 20% | AM39: Only for in-game players | AN39: Off - ilimitado | AO39: =IF(B39=0," ",TIME(,ROUNDDOWN(AG39*AJ39/60,0)*5+(AG39*AJ39),)+B39) -> 0.44167824 | AP39: =IF(Q39=0,,ROUNDUP(Q39/(V39*(1-AC39-AD39)),0)) -> 112 | AQ39: =IFERROR(IF(V39=0," ",IF(V39<=5,"MICRO",IF(V39<=19.8,"LOW",IF(V39<=99.8,"MEDIUM",IF(V39<=500,"HIGH",IF(V39>500,"SUPER HIGH",)))))),"") -> MICRO
A40: MONDAY | B40: 0.41667824 | C40: =TEXT(IF($B40=0," ",$B40-C$6),"hh:mm am/pm") -> 08:00 001/p1 | D40: =TEXT(IF($B40=0," ",$B40-D$6),"hh:mm am/pm") -> 06:00 001/p1 | E40: =TEXT(IF($B40=0," ",$B40-E$6),"hh:mm am/pm") -> 07:00 001/p1 | F40: =TEXT(IF($B40=0," ",$B40-F$6),"hh:mm am/pm") -> 08:00 001/p1 | G40: =TEXT(IF($B40=0," ",$B40-G$6),"hh:mm am/pm") -> 09:00 001/p1 | H40: =TEXT(IF($B40=0," ",$B40+H$6),"hh:mm am/pm") -> 16:00 001/p1 | I40: =TEXT(IF($B40=0," ",$B40+I$6),"hh:mm am/pm") -> 21:00 001/p1 | J40: #AS 4K Battle | L40: #AS Battle | M40: Side Event | N40: NLH | O40: Regular KO 1/2 | P40: 8 | Q40: 800 | R40: n/a | T40: 15% New | U40: Only buy-in | V40: 6 | W40: 6 | Y40: No Limit | AA40: REENTRY | AB40: 5 min | AC40: 0.1 | AD40: 0.02 | AE40: Turbo | AF40: 40000 | AG40: 10 | AH40: 8 | AI40: 8 | AJ40: 14 | AK40: 2-10000 | AL40: Level 0 20% | AM40: Only for in-game players | AN40: Off - ilimitado | AO40: =IF(B40=0," ",TIME(,ROUNDDOWN(AG40*AJ40/60,0)*5+(AG40*AJ40),)+B40) -> 0.52084491 | AP40: =IF(Q40=0,,ROUNDUP(Q40/(V40*(1-AC40-AD40)),0)) -> 152 | AQ40: =IFERROR(IF(V40=0," ",IF(V40<=5,"MICRO",IF(V40<=19.8,"LOW",IF(V40<=99.8,"MEDIUM",IF(V40<=500,"HIGH",IF(V40>500,"SUPER HIGH",)))))),"") -> LOW
B41: 0.41667824 | C41: =TEXT(IF($B41=0," ",$B41-C$6),"hh:mm am/pm") -> 08:00 001/p1 | D41: =TEXT(IF($B41=0," ",$B41-D$6),"hh:mm am/pm") -> 06:00 001/p1 | E41: =TEXT(IF($B41=0," ",$B41-E$6),"hh:mm am/pm") -> 07:00 001/p1 | F41: =TEXT(IF($B41=0," ",$B41-F$6),"hh:mm am/pm") -> 08:00 001/p1 | G41: =TEXT(IF($B41=0," ",$B41-G$6),"hh:mm am/pm") -> 09:00 001/p1 | H41: =TEXT(IF($B41=0," ",$B41+H$6),"hh:mm am/pm") -> 16:00 001/p1 | I41: =TEXT(IF($B41=0," ",$B41+I$6),"hh:mm am/pm") -> 21:00 001/p1 | J41: 1K Plus | L41: Plus | M41: Side Event | N41: NLH | O41: OFF | P41: 9 | Q41: 200 | R41: n/a | T41: 20% Flat | U41: Only buy-in | V41: 0.4 | W41: 0.4 | Y41: No limit + double rebuy | Z41: 0.4 | AA41: 80000 | AB41: 5 min | AC41: 0.1 | AD41: 0 | AE41: Turbo | AF41: 40000 | AG41: 7 | AH41: 6 | AI41: 6 | AJ41: 15 | AK41: 2-10000 | AL41: Level 0 20% | AM41: Only for in-game players | AN41: Off - ilimitado | AO41: =IF(B41=0," ",TIME(,ROUNDDOWN(AG41*AJ41/60,0)*5+(AG41*AJ41),)+B41) -> 0.49306713 | AP41: =IF(Q41=0,,ROUNDUP(Q41/(V41*(1-AC41-AD41)),0)) -> 556 | AQ41: =IFERROR(IF(V41=0," ",IF(V41<=5,"MICRO",IF(V41<=19.8,"LOW",IF(V41<=99.8,"MEDIUM",IF(V41<=500,"HIGH",IF(V41>500,"SUPER HIGH",)))))),"") -> MICRO
B42: 0.41667824 | C42: =TEXT(IF($B42=0," ",$B42-C$6),"hh:mm am/pm") -> 08:00 001/p1 | D42: =TEXT(IF($B42=0," ",$B42-D$6),"hh:mm am/pm") -> 06:00 001/p1 | E42: =TEXT(IF($B42=0," ",$B42-E$6),"hh:mm am/pm") -> 07:00 001/p1 | F42: =TEXT(IF($B42=0," ",$B42-F$6),"hh:mm am/pm") -> 08:00 001/p1 | G42: =TEXT(IF($B42=0," ",$B42-G$6),"hh:mm am/pm") -> 09:00 001/p1 | H42: =TEXT(IF($B42=0," ",$B42+H$6),"hh:mm am/pm") -> 16:00 001/p1 | I42: =TEXT(IF($B42=0," ",$B42+I$6),"hh:mm am/pm") -> 21:00 001/p1 | J42: #AS 3K Plus | L42: #AS Plus | M42: Side Event | N42: NLH | O42: OFF | P42: 9 | Q42: 600 | R42: n/a | T42: 20% Flat | U42: Only buy-in | V42: 1.6 | W42: 1.6 | Y42: No limit + double rebuy | Z42: 1.6 | AA42: 160000 | AB42: 5 min | AC42: 0.1 | AD42: 0.02 | AE42: Turbo | AF42: 40000 | AG42: 8 | AH42: 7 | AI42: 7 | AJ42: 15 | AK42: 2-10000 | AL42: Level 0 20% | AM42: Only for in-game players | AN42: Off - ilimitado | AO42: =IF(B42=0," ",TIME(,ROUNDDOWN(AG42*AJ42/60,0)*5+(AG42*AJ42),)+B42) -> 0.50695602 | AP42: =IF(Q42=0,,ROUNDUP(Q42/(V42*(1-AC42-AD42)),0)) -> 427 | AQ42: =IFERROR(IF(V42=0," ",IF(V42<=5,"MICRO",IF(V42<=19.8,"LOW",IF(V42<=99.8,"MEDIUM",IF(V42<=500,"HIGH",IF(V42>500,"SUPER HIGH",)))))),"") -> MICRO
...

Sheet MTTS BRAZIL
A1: z
A2: =SUM(Q3:R3) -> 556 | C2: MTT - BRAZIL
A3: 5 | B3: Brazil | C3: MTT | D3: TIPO | E3: MODALIDADE | F3: K.O (REG / PROG / MYSTERY/ OFF) | G3: GUARANTEED | H3: BUY-IN | I3: REENTRY/REBUY | J3: ADD-ON | K3: STACK INICIAL | L3: STACK REENTRY/REBUY | M3: STACK ADD-ON | N3: BLINDS UP (min) | Q3: =COUNTIF($D1:$D997,"Main event") -> 65 | R3: =COUNTIF($D1:$D997,"side event") -> 491 | S3: =COUNTIF($D1:$D997,"sat") -> 266
A4: DAY | B4: TIME (UTC -3) | N4: Early game | O4: Pós Late Reg. | P4: Final Table | Q4: LATE REG. | R4: Hora late register | S4: Size buy-in
A6: SEGUNDA-FEIRA | C6: SEGUNDA-FEIRA | H6: SEGUNDA-FEIRA
A7: SEGUNDA-FEIRA | B7: ='G MTTS'!B7 -> 0.58334491 | C7: ='G MTTS'!J7 -> #AS 25K WarmUp | D7: ='G MTTS'!M7 -> Main Event | E7: ='G MTTS'!N7 -> NLH | F7: ='G MTTS'!O7 -> Progressive KO 1/3 | G7: =IF('G MTTS'!Q7=0," ",'G MTTS'!Q7*$A$3) -> 25000 | H7: =IF('G MTTS'!V7=0," ",'G MTTS'!V7*$A$3) -> 110 | I7: =IF('G MTTS'!W7=0," ",'G MTTS'!W7*$A$3) -> 110 | J7: =IF('G MTTS'!Z7=0," ",'G MTTS'!Z7*$A$3) | K7: ='G MTTS'!AF7 -> 50000 | L7: ='G MTTS'!X7 -> 0 | M7: ='G MTTS'!AA7 -> REENTRY | N7: ='G MTTS'!AG7 -> 12 | O7: ='G MTTS'!AH7 -> 10 | P7: ='G MTTS'!AI7 -> 10 | Q7: ='G MTTS'!AJ7 -> 15 | R7: =IF(B7=0," ",TIME(,ROUNDDOWN(N7*Q7/60,0)*5+(N7*Q7),)+B7) -> 0.71876157 | S7: =IFERROR(IF(H7=0," ",IF(H7<=25,"MICRO",IF(H7<=99,"LOW",IF(H7<=499,"MEDIUM",IF(H7<=2500,"HIGH",IF(H7>2500,"SUPER HIGH",)))))),"") -> MEDIUM
A8: Side Event | B8: ='G MTTS'!B8 -> 0.62501157 | C8: ='G MTTS'!J8 -> #AS 25K Plus+SPS | D8: ='G MTTS'!M8 -> Main Event | E8: ='G MTTS'!N8 -> NLH | F8: ='G MTTS'!O8 -> OFF | G8: =IF('G MTTS'!Q8=0," ",'G MTTS'!Q8*$A$3) -> 26000 | H8: =IF('G MTTS'!V8=0," ",'G MTTS'!V8*$A$3) -> 55 | I8: =IF('G MTTS'!W8=0," ",'G MTTS'!W8*$A$3) -> 55 | J8: =IF('G MTTS'!Z8=0," ",'G MTTS'!Z8*$A$3) -> 55 | K8: ='G MTTS'!AF8 -> 40000 | L8: ='G MTTS'!X8 -> 0 | M8: ='G MTTS'!AA8 -> 120000 | N8: ='G MTTS'!AG8 -> 10 | O8: ='G MTTS'!AH8 -> 10 | P8: ='G MTTS'!AI8 -> 10 | Q8: ='G MTTS'!AJ8 -> 15 | R8: =IF(B8=0," ",TIME(,ROUNDDOWN(N8*Q8/60,0)*5+(N8*Q8),)+B8) -> 0.73612269 | S8: =IFERROR(IF(H8=0," ",IF(H8<=25,"MICRO",IF(H8<=99,"LOW",IF(H8<=499,"MEDIUM",IF(H8<=2500,"HIGH",IF(H8>2500,"SUPER HIGH",)))))),"") -> LOW
A9: =COUNTIF(D7:D77,"Side event") -> 60 | B9: ='G MTTS'!B9 -> 0.66667824 | C9: ='G MTTS'!J9 -> #AS 20K Bounty | D9: ='G MTTS'!M9 -> Main Event | E9: ='G MTTS'!N9 -> NLH | F9: ='G MTTS'!O9 -> Progressive KO 1/2 | G9: =IF('G MTTS'!Q9=0," ",'G MTTS'!Q9*$A$3) -> 20000 | H9: =IF('G MTTS'!V9=0," ",'G MTTS'!V9*$A$3) -> 80 | I9: =IF('G MTTS'!W9=0," ",'G MTTS'!W9*$A$3) -> 80 | J9: =IF('G MTTS'!Z9=0," ",'G MTTS'!Z9*$A$3) | K9: ='G MTTS'!AF9 -> 50000 | L9: ='G MTTS'!X9 -> 60000 | M9: ='G MTTS'!AA9 -> REENTRY | N9: ='G MTTS'!AG9 -> 12 | O9: ='G MTTS'!AH9 -> 10 | P9: ='G MTTS'!AI9 -> 10 | Q9: ='G MTTS'!AJ9 -> 15 | R9: =IF(B9=0," ",TIME(,ROUNDDOWN(N9*Q9/60,0)*5+(N9*Q9),)+B9) -> 0.80209491 | S9: =IFERROR(IF(H9=0," ",IF(H9<=25,"MICRO",IF(H9<=99,"LOW",IF(H9<=499,"MEDIUM",IF(H9<=2500,"HIGH",IF(H9>2500,"SUPER HIGH",)))))),"") -> LOW
A10: Main Event | B10: ='G MTTS'!B10 -> 0.75001157 | C10: ='G MTTS'!J10 -> #AS 75K Big Plus+SPS | D10: ='G MTTS'!M10 -> Main Event | E10: ='G MTTS'!N10 -> NLH | F10: ='G MTTS'!O10 -> OFF | G10: =IF('G MTTS'!Q10=0," ",'G MTTS'!Q10*$A$3) -> 76000 | H10: =IF('G MTTS'!V10=0," ",'G MTTS'!V10*$A$3) -> 75 | I10: =IF('G MTTS'!W10=0," ",'G MTTS'!W10*$A$3) -> 75 | J10: =IF('G MTTS'!Z10=0," ",'G MTTS'!Z10*$A$3) -> 75 | K10: ='G MTTS'!AF10 -> 40000 | L10: ='G MTTS'!X10 -> 0 | M10: ='G MTTS'!AA10 -> 120000 | N10: ='G MTTS'!AG10 -> 12 | O10: ='G MTTS'!AH10 -> 10 | P10: ='G MTTS'!AI10 -> 10 | Q10: ='G MTTS'!AJ10 -> 15 | R10: =IF(B10=0," ",TIME(,ROUNDDOWN(N10*Q10/60,0)*5+(N10*Q10),)+B10) -> 0.88542824 | S10: =IFERROR(IF(H10=0," ",IF(H10<=25,"MICRO",IF(H10<=99,"LOW",IF(H10<=499,"MEDIUM",IF(H10<=2500,"HIGH",IF(H10>2500,"SUPER HIGH",)))))),"") -> LOW
A11: =COUNTIF(D7:D77,"Main Event") -> 10 | B11: ='G MTTS'!B11 -> 0.75001157 | C11: ='G MTTS'!J11 -> #AS 100K Plus+SPT | D11: ='G MTTS'!M11 -> Main Event | E11: ='G MTTS'!N11 -> NLH | F11: ='G MTTS'!O11 -> OFF | G11: =IF('G MTTS'!Q11=0," ",'G MTTS'!Q11*$A$3) -> 108500 | H11: =IF('G MTTS'!V11=0," ",'G MTTS'!V11*$A$3) -> 25 | I11: =IF('G MTTS'!W11=0," ",'G MTTS'!W11*$A$3) -> 25 | J11: =IF('G MTTS'!Z11=0," ",'G MTTS'!Z11*$A$3) -> 30 | K11: ='G MTTS'!AF11 -> 50000 | L11: ='G MTTS'!X11 -> 0 | M11: ='G MTTS'!AA11 -> 250000 | N11: ='G MTTS'!AG11 -> 10 | O11: ='G MTTS'!AH11 -> 8 | P11: ='G MTTS'!AI11 -> 10 | Q11: ='G MTTS'!AJ11 -> 15 | R11: =IF(B11=0," ",TIME(,ROUNDDOWN(N11*Q11/60,0)*5+(N11*Q11),)+B11) -> 0.86112269 | S11: =IFERROR(IF(H11=0," ",IF(H11<=25,"MICRO",IF(H11<=99,"LOW",IF(H11<=499,"MEDIUM",IF(H11<=2500,"HIGH",IF(H11>2500,"SUPER HIGH",)))))),"") -> MICRO
A12: total GTD | B12: ='G MTTS'!B12 -> 0.77084491 | C12: ='G MTTS'!J12 -> #AS 100K Battle+SPS | D12: ='G MTTS'!M12 -> Main Event | E12: ='G MTTS'!N12 -> NLH | F12: ='G MTTS'!O12 -> Progressive KO 1/2 | G12: =IF('G MTTS'!Q12=0," ",'G MTTS'!Q12*$A$3) -> 101000 | H12: =IF('G MTTS'!V12=0," ",'G MTTS'!V12*$A$3) -> 75 | I12: =IF('G MTTS'!W12=0," ",'G MTTS'!W12*$A$3) -> 75 | J12: =IF('G MTTS'!Z12=0," ",'G MTTS'!Z12*$A$3) | K12: ='G MTTS'!AF12 -> 80000 | L12: ='G MTTS'!X12 -> 0 | M12: ='G MTTS'!AA12 -> REENTRY | N12: ='G MTTS'!AG12 -> 12 | O12: ='G MTTS'!AH12 -> 10 | P12: ='G MTTS'!AI12 -> 10 | Q12: ='G MTTS'!AJ12 -> 15 | R12: =IF(B12=0," ",TIME(,ROUNDDOWN(N12*Q12/60,0)*5+(N12*Q12),)+B12) -> 0.90626157 | S12: =IFERROR(IF(H12=0," ",IF(H12<=25,"MICRO",IF(H12<=99,"LOW",IF(H12<=499,"MEDIUM",IF(H12<=2500,"HIGH",IF(H12>2500,"SUPER HIGH",)))))),"") -> LOW
A13: =SUM(G7:G77,G80:G126) -> 1256475 | B13: ='G MTTS'!B13 -> 0.79167824 | C13: ='G MTTS'!J13 -> #AS 300K Monday HighS | D13: ='G MTTS'!M13 -> Main Event | E13: ='G MTTS'!N13 -> NLH | F13: ='G MTTS'!O13 -> Progressive KO 1/2 | G13: =IF('G MTTS'!Q13=0," ",'G MTTS'!Q13*$A$3) -> 300000 | H13: =IF('G MTTS'!V13=0," ",'G MTTS'!V13*$A$3) -> 750 | I13: =IF('G MTTS'!W13=0," ",'G MTTS'!W13*$A$3) -> 750 | J13: =IF('G MTTS'!Z13=0," ",'G MTTS'!Z13*$A$3) | K13: ='G MTTS'!AF13 -> 50000 | L13: ='G MTTS'!X13 -> 60000 | M13: ='G MTTS'!AA13 -> REENTRY | N13: ='G MTTS'!AG13 -> 15 | O13: ='G MTTS'!AH13 -> 12 | P13: ='G MTTS'!AI13 -> 12 | Q13: ='G MTTS'!AJ13 -> 14 | R13: =IF(B13=0," ",TIME(,ROUNDDOWN(N13*Q13/60,0)*5+(N13*Q13),)+B13) -> 0.94792824 | S13: =IFERROR(IF(H13=0," ",IF(H13<=25,"MICRO",IF(H13<=99,"LOW",IF(H13<=499,"MEDIUM",IF(H13<=2500,"HIGH",IF(H13>2500,"SUPER HIGH",)))))),"") -> HIGH
B14: ='G MTTS'!B14 -> 0.79167824 | C14: ='G MTTS'!J14 -> #AS 150K Battle HR+SPS | D14: ='G MTTS'!M14 -> Main Event | E14: ='G MTTS'!N14 -> NLH | F14: ='G MTTS'!O14 -> Progressive KO 1/2 | G14: =IF('G MTTS'!Q14=0," ",'G MTTS'!Q14*$A$3) -> 151500 | H14: =IF('G MTTS'!V14=0," ",'G MTTS'!V14*$A$3) -> 250 | I14: =IF('G MTTS'!W14=0," ",'G MTTS'!W14*$A$3) -> 250 | J14: =IF('G MTTS'!Z14=0," ",'G MTTS'!Z14*$A$3) | K14: ='G MTTS'!AF14 -> 50000 | L14: ='G MTTS'!X14 -> 60000 | M14: ='G MTTS'!AA14 -> REENTRY | N14: ='G MTTS'!AG14 -> 12 | O14: ='G MTTS'!AH14 -> 12 | P14: ='G MTTS'!AI14 -> 12 | Q14: ='G MTTS'!AJ14 -> 15 | R14: =IF(B14=0," ",TIME(,ROUNDDOWN(N14*Q14/60,0)*5+(N14*Q14),)+B14) -> 0.92709491 | S14: =IFERROR(IF(H14=0," ",IF(H14<=25,"MICRO",IF(H14<=99,"LOW",IF(H14<=499,"MEDIUM",IF(H14<=2500,"HIGH",IF(H14>2500,"SUPER HIGH",)))))),"") -> MEDIUM
A15: SEGUNDA-FEIRA | B15: ='G MTTS'!B15 -> 0.83334491 | C15: ='G MTTS'!J15 -> #AS 60K OmaX HR | D15: ='G MTTS'!M15 -> Main Event | E15: ='G MTTS'!N15 -> PLO5 | F15: ='G MTTS'!O15 -> Progressive KO 1/2 | G15: =IF('G MTTS'!Q15=0," ",'G MTTS'!Q15*$A$3) -> 60000 | H15: =IF('G MTTS'!V15=0," ",'G MTTS'!V15*$A$3) -> 550 | I15: =IF('G MTTS'!W15=0," ",'G MTTS'!W15*$A$3) -> 550 | J15: =IF('G MTTS'!Z15=0," ",'G MTTS'!Z15*$A$3) | K15: ='G MTTS'!AF15 -> 50000 | L15: ='G MTTS'!X15 -> 60000 | M15: ='G MTTS'!AA15 -> REENTRY | N15: ='G MTTS'!AG15 -> 12 | O15: ='G MTTS'!AH15 -> 12 | P15: ='G MTTS'!AI15 -> 12 | Q15: ='G MTTS'!AJ15 -> 15 | R15: =IF(B15=0," ",TIME(,ROUNDDOWN(N15*Q15/60,0)*5+(N15*Q15),)+B15) -> 0.96876157 | S15: =IFERROR(IF(H15=0," ",IF(H15<=25,"MICRO",IF(H15<=99,"LOW",IF(H15<=499,"MEDIUM",IF(H15<=2500,"HIGH",IF(H15>2500,"SUPER HIGH",)))))),"") -> HIGH
B16: ='G MTTS'!B16 -> 0.83334491 | C16: ='G MTTS'!J16 -> #AS 50K Big Mystery+SPS | D16: ='G MTTS'!M16 -> Main Event | E16: ='G MTTS'!N16 -> NLH | F16: ='G MTTS'!O16 -> Mystery Bounty 1/2 | G16: =IF('G MTTS'!Q16=0," ",'G MTTS'!Q16*$A$3) -> 51000 | H16: =IF('G MTTS'!V16=0," ",'G MTTS'!V16*$A$3) -> 110 | I16: =IF('G MTTS'!W16=0," ",'G MTTS'!W16*$A$3) -> 110 | J16: =IF('G MTTS'!Z16=0," ",'G MTTS'!Z16*$A$3) | K16: ='G MTTS'!AF16 -> 60000 | L16: ='G MTTS'!X16 -> 0 | M16: ='G MTTS'!AA16 -> REENTRY | N16: ='G MTTS'!AG16 -> 10 | O16: ='G MTTS'!AH16 -> 10 | P16: ='G MTTS'!AI16 -> 10 | Q16: ='G MTTS'!AJ16 -> 14 | R16: =IF(B16=0," ",TIME(,ROUNDDOWN(N16*Q16/60,0)*5+(N16*Q16),)+B16) -> 0.93751157 | S16: =IFERROR(IF(H16=0," ",IF(H16<=25,"MICRO",IF(H16<=99,"LOW",IF(H16<=499,"MEDIUM",IF(H16<=2500,"HIGH",IF(H16>2500,"SUPER HIGH",)))))),"") -> MEDIUM
B17: ='G MTTS'!B17 -> 0 | C17: ='G MTTS'!J17 -> 0 | D17: ='G MTTS'!M17 -> 0 | E17: ='G MTTS'!N17 -> 0 | F17: ='G MTTS'!O17 -> 0 | G17: =IF('G MTTS'!Q17=0," ",'G MTTS'!Q17*5) | H17: =IF('G MTTS'!V17=0," ",'G MTTS'!V17*5) | I17: =IF('G MTTS'!W17=0," ",'G MTTS'!W17*5) | K17: ='G MTTS'!AF17 -> 0 | L17: ='G MTTS'!X17 -> 0 | M17: ='G MTTS'!AA17 -> 0 | N17: ='G MTTS'!AG17 -> 0 | O17: ='G MTTS'!AH17 -> 0 | P17: ='G MTTS'!AI17 -> 0 | Q17: ='G MTTS'!AJ17 -> 0 | R17: =IF(B17=0," ",TIME(,ROUNDDOWN(N17*Q17/60,0)*5+(N17*Q17),)+B17)
A18: SEGUNDA-FEIRA | B18: ='G MTTS'!B18 -> 1.1574074e-05 | C18: ='G MTTS'!J18 -> #AS 6K Sonic+SPS | D18: ='G MTTS'!M18 -> Side Event | E18: ='G MTTS'!N18 -> NLH | F18: ='G MTTS'!O18 -> OFF | G18: =IF('G MTTS'!Q18=0," ",'G MTTS'!Q18*$A$3) -> 7000 | H18: =IF('G MTTS'!V18=0," ",'G MTTS'!V18*$A$3) -> 35 | I18: =IF('G MTTS'!W18=0," ",'G MTTS'!W18*$A$3) -> 35 | J18: =IF('G MTTS'!Z18=0," ",'G MTTS'!Z18*$A$3) | K18: ='G MTTS'!AF18 -> 50000 | L18: ='G MTTS'!X18 -> 0 | M18: ='G MTTS'!AA18 -> REENTRY | N18: ='G MTTS'!AG18 -> 6 | O18: ='G MTTS'!AH18 -> 5 | P18: ='G MTTS'!AI18 -> 5 | Q18: ='G MTTS'!AJ18 -> 13 | R18: =IF(B18=0," ",TIME(,ROUNDDOWN(N18*Q18/60,0)*5+(N18*Q18),)+B18) -> 0.057650463 | S18: =IFERROR(IF(H18=0," ",IF(H18<=25,"MICRO",IF(H18<=99,"LOW",IF(H18<=499,"MEDIUM",IF(H18<=2500,"HIGH",IF(H18>2500,"SUPER HIGH",)))))),"") -> LOW
B19: ='G MTTS'!B19 -> 1.1574074e-05 | C19: ='G MTTS'!J19 -> 1.2K Omax K.O | D19: ='G MTTS'!M19 -> Side Event | E19: ='G MTTS'!N19 -> PLO5 | F19: ='G MTTS'!O19 -> Regular KO 1/3 | G19: =IF('G MTTS'!Q19=0," ",'G MTTS'!Q19*$A$3) -> 1200 | H19: =IF('G MTTS'!V19=0," ",'G MTTS'!V19*$A$3) -> 10 | I19: =IF('G MTTS'!W19=0," ",'G MTTS'!W19*$A$3) -> 10 | J19: =IF('G MTTS'!Z19=0," ",'G MTTS'!Z19*$A$3) | K19: ='G MTTS'!AF19 -> 60000 | L19: ='G MTTS'!X19 -> 0 | M19: ='G MTTS'!AA19 -> REENTRY | N19: ='G MTTS'!AG19 -> 6 | O19: ='G MTTS'!AH19 -> 5 | P19: ='G MTTS'!AI19 -> 5 | Q19: ='G MTTS'!AJ19 -> 12 | R19: =IF(B19=0," ",TIME(,ROUNDDOWN(N19*Q19/60,0)*5+(N19*Q19),)+B19) -> 0.053483796 | S19: =IFERROR(IF(H19=0," ",IF(H19<=25,"MICRO",IF(H19<=99,"LOW",IF(H19<=499,"MEDIUM",IF(H19<=2500,"HIGH",IF(H19>2500,"SUPER HIGH",)))))),"") -> MICRO
B20: ='G MTTS'!B20 -> 0.013900463 | C20: ='G MTTS'!J20 -> 600 Battle Turbo | D20: ='G MTTS'!M20 -> Side Event | E20: ='G MTTS'!N20 -> NLH | F20: ='G MTTS'!O20 -> Regular KO 1/3 | G20: =IF('G MTTS'!Q20=0," ",'G MTTS'!Q20*$A$3) -> 600 | H20: =IF('G MTTS'!V20=0," ",'G MTTS'!V20*$A$3) -> 5 | I20: =IF('G MTTS'!W20=0," ",'G MTTS'!W20*$A$3) -> 5 | J20: =IF('G MTTS'!Z20=0," ",'G MTTS'!Z20*$A$3) | K20: ='G MTTS'!AF20 -> 15000 | L20: ='G MTTS'!X20 -> 0 | M20: ='G MTTS'!AA20 -> REENTRY | N20: ='G MTTS'!AG20 -> 6 | O20: ='G MTTS'!AH20 -> 5 | P20: ='G MTTS'!AI20 -> 5 | Q20: ='G MTTS'!AJ20 -> 13 | R20: =IF(B20=0," ",TIME(,ROUNDDOWN(N20*Q20/60,0)*5+(N20*Q20),)+B20) -> 0.071539352 | S20: =IFERROR(IF(H20=0," ",IF(H20<=25,"MICRO",IF(H20<=99,"LOW",IF(H20<=499,"MEDIUM",IF(H20<=2500,"HIGH",IF(H20>2500,"SUPER HIGH",)))))),"") -> MICRO
A21: SEGUNDA-FEIRA | B21: ='G MTTS'!B21 -> 0.020844907 | C21: ='G MTTS'!J21 -> 750 Plus | D21: ='G MTTS'!M21 -> Side Event | E21: ='G MTTS'!N21 -> NLH | F21: ='G MTTS'!O21 -> OFF | G21: =IF('G MTTS'!Q21=0," ",'G MTTS'!Q21*$A$3) -> 750 | H21: =IF('G MTTS'!V21=0," ",'G MTTS'!V21*$A$3) -> 2 | I21: =IF('G MTTS'!W21=0," ",'G MTTS'!W21*$A$3) -> 2 | J21: =IF('G MTTS'!Z21=0," ",'G MTTS'!Z21*$A$3) -> 2 | K21: ='G MTTS'!AF21 -> 30000 | L21: ='G MTTS'!X21 -> 0 | M21: ='G MTTS'!AA21 -> 50000 | N21: ='G MTTS'!AG21 -> 5 | O21: ='G MTTS'!AH21 -> 5 | P21: ='G MTTS'!AI21 -> 5 | Q21: ='G MTTS'!AJ21 -> 13 | R21: =IF(B21=0," ",TIME(,ROUNDDOWN(N21*Q21/60,0)*5+(N21*Q21),)+B21) -> 0.069456019 | S21: =IFERROR(IF(H21=0," ",IF(H21<=25,"MICRO",IF(H21<=99,"LOW",IF(H21<=499,"MEDIUM",IF(H21<=2500,"HIGH",IF(H21>2500,"SUPER HIGH",)))))),"") -> MICRO
B22: ='G MTTS'!B22 -> 0.020844907 | C22: ='G MTTS'!J22 -> #AS 1.2K Omax | D22: ='G MTTS'!M22 -> Side Event | E22: ='G MTTS'!N22 -> PLO5 | F22: ='G MTTS'!O22 -> OFF | G22: =IF('G MTTS'!Q22=0," ",'G MTTS'!Q22*$A$3) -> 1200 | H22: =IF('G MTTS'!V22=0," ",'G MTTS'!V22*$A$3) -> 5 | I22: =IF('G MTTS'!W22=0," ",'G MTTS'!W22*$A$3) -> 5 | J22: =IF('G MTTS'!Z22=0," ",'G MTTS'!Z22*$A$3) -> 5 | K22: ='G MTTS'!AF22 -> 30000 | L22: ='G MTTS'!X22 -> 0 | M22: ='G MTTS'!AA22 -> 70000 | N22: ='G MTTS'!AG22 -> 6 | O22: ='G MTTS'!AH22 -> 5 | P22: ='G MTTS'!AI22 -> 5 | Q22: ='G MTTS'!AJ22 -> 12 | R22: =IF(B22=0," ",TIME(,ROUNDDOWN(N22*Q22/60,0)*5+(N22*Q22),)+B22) -> 0.07431713 | S22: =IFERROR(IF(H22=0," ",IF(H22<=25,"MICRO",IF(H22<=99,"LOW",IF(H22<=499,"MEDIUM",IF(H22<=2500,"HIGH",IF(H22>2500,"SUPER HIGH",)))))),"") -> MICRO
B23: ='G MTTS'!B23 -> 0.041678241 | C23: ='G MTTS'!J23 -> #AS 8K Plus | D23: ='G MTTS'!M23 -> Side Event | E23: ='G MTTS'!N23 -> NLH | F23: ='G MTTS'!O23 -> OFF | G23: =IF('G MTTS'!Q23=0," ",'G MTTS'!Q23*$A$3) -> 8000 | H23: =IF('G MTTS'!V23=0," ",'G MTTS'!V23*$A$3) -> 15 | I23: =IF('G MTTS'!W23=0," ",'G MTTS'!W23*$A$3) -> 15 | J23: =IF('G MTTS'!Z23=0," ",'G MTTS'!Z23*$A$3) -> 15 | K23: ='G MTTS'!AF23 -> 40000 | L23: ='G MTTS'!X23 -> 0 | M23: ='G MTTS'!AA23 -> 160000 | N23: ='G MTTS'!AG23 -> 6 | O23: ='G MTTS'!AH23 -> 5 | P23: ='G MTTS'!AI23 -> 5 | Q23: ='G MTTS'!AJ23 -> 13 | R23: =IF(B23=0," ",TIME(,ROUNDDOWN(N23*Q23/60,0)*5+(N23*Q23),)+B23) -> 0.09931713 | S23: =IFERROR(IF(H23=0," ",IF(H23<=25,"MICRO",IF(H23<=99,"LOW",IF(H23<=499,"MEDIUM",IF(H23<=2500,"HIGH",IF(H23>2500,"SUPER HIGH",)))))),"") -> MICRO
A24: SEGUNDA-FEIRA | B24: ='G MTTS'!B24 -> 0.041678241 | C24: ='G MTTS'!J24 -> #AS 2.5K Omax K.O | D24: ='G MTTS'!M24 -> Side Event | E24: ='G MTTS'!N24 -> PLO4 | F24: ='G MTTS'!O24 -> Regular KO 1/3 | G24: =IF('G MTTS'!Q24=0," ",'G MTTS'!Q24*$A$3) -> 2500 | H24: =IF('G MTTS'!V24=0," ",'G MTTS'!V24*$A$3) -> 50 | I24: =IF('G MTTS'!W24=0," ",'G MTTS'!W24*$A$3) -> 50 | J24: =IF('G MTTS'!Z24=0," ",'G MTTS'!Z24*$A$3) | K24: ='G MTTS'!AF24 -> 50000 | L24: ='G MTTS'!X24 -> 0 | M24: ='G MTTS'!AA24 -> REENTRY | N24: ='G MTTS'!AG24 -> 6 | O24: ='G MTTS'!AH24 -> 5 | P24: ='G MTTS'!AI24 -> 5 | Q24: ='G MTTS'!AJ24 -> 15 | R24: =IF(B24=0," ",TIME(,ROUNDDOWN(N24*Q24/60,0)*5+(N24*Q24),)+B24) -> 0.10765046 | S24: =IFERROR(IF(H24=0," ",IF(H24<=25,"MICRO",IF(H24<=99,"LOW",IF(H24<=499,"MEDIUM",IF(H24<=2500,"HIGH",IF(H24>2500,"SUPER HIGH",)))))),"") -> LOW
